Workbook

Sheet Datos Iniciales
A1: CICLO | B1: TÉCNICO EN EMERGENCIAS SANITARIAS
A2: NIVEL | B2: GM
A3: MODULO | B3: DOTACIÓN SANITARIA
A4: CÓDIGO MÓDULO | B4: 0054
A7: Tabla 1 - Resultados de aprendizaje y sus pesos | E7: Tabla 2 - Unidades de trabajo (UT) y sus pesos respecto de los Resultados de Aprendizaje (RA) | S7: Listado 1 - Alumnos
A8: NumRA | B8: Resultado de Aprendizaje (Enunciado) | C8: Peso RA | E8: NumUT | F8: =A9 -> RA1 | G8: =A10 -> RA2 | H8: =A11 -> RA3 | I8: =A12 -> RA4 | J8: =A13 -> RA5 | K8: =A14 -> RA6 | L8: =A15 -> RA7 | M8: =A16 -> RA8 | N8: =A17 -> RA9 | O8: =A18 -> RA10 | S8: NumAlumno | T8: Nombre Alumno
A9: RA1 | B9: Realiza el mantenimiento básico de la dotación sanitaria del vehículo interpretando y ejecutando las recomendaciones de los fabricantes de los equipos. | C9: 0.2 | E9: UT1 | F9: 0.05 | G9: 0.07 | H9: 0 | I9: 0 | J9: 0 | K9: 0 | L9: 0 | M9: 0 | N9: 0 | O9: 0 | S9: 1 | T9: Alumno1
A10: RA2 | B10: Controla las existencias y materiales del vehículo sanitario identificando sus características y necesidades de almacenamiento. | C10: 0.6 | E10: UT2 | F10: 0.35 | G10: 0.43 | H10: 0.06 | I10: 0 | J10: 0 | K10: 0 | L10: 0 | M10: 0 | N10: 0 | O10: 0 | S10: 2 | T10: Alumno2
A11: RA3 | B11: Esteriliza el material, relacionando los procedimientos con la seguridad de su ejecución. | C11: 0.15 | E11: UT3 | F11: 0.2 | G11: 0.08 | H11: 0.34 | I11: 0 | J11: 0 | K11: 0 | L11: 0 | M11: 0 | N11: 0 | O11: 0 | S11: 3 | T11: Alumno3
A12: RA4 | B12: Complementa la documentación clínico y no clínica de su competencia, relacionándola con su utilidad y analizando la información tipo que debe constar. | C12: 0.05 | E12: UT4 | F12: 0.25 | G12: 0.14 | H12: 0.15 | I12: 0.25 | J12: 0 | K12: 0 | L12: 0 | M12: 0 | N12: 0 | O12: 0 | S12: 4 | T12: Alumno4
A13: RA5 | B13: RA5 | C13: 0 | E13: UT5 | F13: 0.15 | G13: 0.12 | H13: 0.12 | I13: 0.25 | J13: 0 | K13: 0 | L13: 0 | M13: 0 | N13: 0 | O13: 0 | S13: 5 | T13: Alumno5
A14: RA6 | B14: RA6 | C14: 0 | E14: UT6 | F14: 0 | G14: 0.16 | H14: 0.33 | I14: 0.5 | J14: 0 | K14: 0 | L14: 0 | M14: 0 | N14: 0 | O14: 0 | S14: 6 | T14: Alumno6
A15: RA7 | B15: RA7 | C15: 0 | E15: UT7 | F15: 0 | G15: 0 | H15: 0 | I15: 0 | J15: 0 | K15: 0 | L15: 0 | M15: 0 | N15: 0 | O15: 0 | S15: 7 | T15: Alumno7
A16: RA8 | B16: RA8 | C16: 0 | E16: UT8 | F16: 0 | G16: 0 | H16: 0 | I16: 0 | J16: 0 | K16: 0 | L16: 0 | M16: 0 | N16: 0 | O16: 0 | S16: 8 | T16: Alumno8
A17: RA9 | B17: RA9 | C17: 0 | E17: UT9 | F17: 0 | G17: 0 | H17: 0 | I17: 0 | J17: 0 | K17: 0 | L17: 0 | M17: 0 | N17: 0 | O17: 0 | S17: 9 | T17: Alumno9
A18: RA10 | B18: RA10 | C18: 0 | E18: UT10 | F18: 0 | G18: 0 | H18: 0 | I18: 0 | J18: 0 | K18: 0 | L18: 0 | M18: 0 | N18: 0 | O18: 0 | S18: 10 | T18: Alumno10
B19: Total | C19: =SUM(C9:C18) -> 1 | E19: UT11 | F19: 0 | G19: 0 | H19: 0 | I19: 0 | J19: 0 | K19: 0 | L19: 0 | M19: 0 | N19: 0 | O19: 0 | S19: 11 | T19: Alumno11
E20: UT12 | F20: 0 | G20: 0 | H20: 0 | I20: 0 | J20: 0 | K20: 0 | L20: 0 | M20: 0 | N20: 0 | O20: 0 | S20: 12 | T20: Alumno12
E21: UT13 | F21: 0 | G21: 0 | H21: 0 | I21: 0 | J21: 0 | K21: 0 | L21: 0 | M21: 0 | N21: 0 | O21: 0 | S21: 13 | T21: Alumno13
E22: UT14 | F22: 0 | G22: 0 | H22: 0 | I22: 0 | J22: 0 | K22: 0 | L22: 0 | M22: 0 | N22: 0 | O22: 0 | S22: 14 | T22: Alumno14
E23: UT15 | F23: 0 | G23: 0 | H23: 0 | I23: 0 | J23: 0 | K23: 0 | L23: 0 | M23: 0 | N23: 0 | O23: 0 | S23: 15 | T23: Alumno15
E24: UT16 | F24: 0 | G24: 0 | H24: 0 | I24: 0 | J24: 0 | K24: 0 | L24: 0 | M24: 0 | N24: 0 | O24: 0 | S24: 16 | T24: Alumno16
E25: UT17 | F25: 0 | G25: 0 | H25: 0 | I25: 0 | J25: 0 | K25: 0 | L25: 0 | M25: 0 | N25: 0 | O25: 0 | S25: 17 | T25: Alumno17
E26: UT18 | F26: 0 | G26: 0 | H26: 0 | I26: 0 | J26: 0 | K26: 0 | L26: 0 | M26: 0 | N26: 0 | O26: 0 | S26: 18 | T26: Alumno18
E27: UT19 | F27: 0 | G27: 0 | H27: 0 | I27: 0 | J27: 0 | K27: 0 | L27: 0 | M27: 0 | N27: 0 | O27: 0 | S27: 19 | T27: Alumno19
E28: UT20 | F28: 0 | G28: 0 | H28: 0 | I28: 0 | J28: 0 | K28: 0 | L28: 0 | M28: 0 | N28: 0 | O28: 0 | S28: 20 | T28: Alumno20
F29: =SUM(F9:F28) -> 1 | G29: =SUM(G9:G28) -> 1 | H29: =SUM(H9:H28) -> 1 | I29: =SUM(I9:I28) -> 1 | J29: =SUM(J9:J28) -> 0 | K29: =SUM(K9:K28) -> 0 | L29: =SUM(L9:L28) -> 0 | M29: =SUM(M9:M28) -> 0 | ... O29: =SUM(O9:O28) -> 0 | S29: 21 | T29: Alumno21
S30: 22 | T30: Alumno22
S31: 23 | T31: Alumno23
S32: 24 | T32: Alumno24
E33: Tabla 3 - Actividades (UT) y sus pesos respecto de los Resultados de Aprendizaje (RA) | S33: 25 | T33: Alumno25
E34: Actividad | F34: =F8 -> RA1 | G34: =G8 -> RA2 | H34: =H8 -> RA3 | I34: =I8 -> RA4 | J34: =J8 -> RA5 | K34: =K8 -> RA6 | L34: =L8 -> RA7 | M34: =M8 -> RA8 | ... O34: =O8 -> RA10 | P34: UT | Q34: EV | S34: 26 | T34: Alumno26
E35: Actividad1 | F35: 0.25 | G35: 0 | H35: 0 | I35: 0 | J35: 0 | K35: 0 | L35: 0 | M35: 0 | N35: 0 | O35: 0 | P35: UT1 | Q35: 1 | S35: 27 | T35: Alumno27
E36: Actividad2 | F36: 0.2 | G36: 0.2 | H36: 0 | I36: 0 | J36: 0 | K36: 0 | L36: 0 | M36: 0 | N36: 0 | O36: 0 | P36: UT1 | Q36: 1 | S36: 28 | T36: Alumno28
E37: Actividad3 | F37: 0.3 | G37: 0.2 | H37: 0.1 | I37: 0 | J37: 0 | K37: 0 | L37: 0 | M37: 0 | N37: 0 | O37: 0 | P37: UT2 | Q37: 1 | S37: 29 | T37: Alumno29
E38: Actividad4 | F38: 0.1 | G38: 0.3 | H38: 0.35 | I38: 0 | J38: 0 | K38: 0 | L38: 0 | M38: 0 | N38: 0 | O38: 0 | P38: UT3 | Q38: 1 | S38: 30 | T38: Alumno30
E39: Actividad5 | F39: 0.05 | G39: 0.1 | H39: 0.3 | I39: 0.1 | J39: 0 | K39: 0 | L39: 0 | M39: 0 | N39: 0 | O39: 0 | P39: UT4 | Q39: 1 | S39: 31 | T39: Alumno31
E40: Actividad6 | F40: 0.1 | G40: 0.15 | H40: 0.1 | I40: 0.4 | J40: 0 | K40: 0 | L40: 0 | M40: 0 | N40: 0 | O40: 0 | P40: UT5 | Q40: 1 | S40: 32 | T40: Alumno32
E41: Actividad7 | F41: 0 | G41: 0.05 | H41: 0.15 | I41: 0.5 | J41: 0 | K41: 0 | L41: 0 | M41: 0 | N41: 0 | O41: 0 | P41: UT6 | Q41: 1 | S41: 33 | T41: Alumno33
E42: Actividad8 | F42: 0 | G42: 0 | H42: 0 | I42: 0 | J42: 0 | K42: 0 | L42: 0 | M42: 0 | N42: 0 | O42: 0 | S42: 34 | T42: Alumno34
...

Sheet Actividades
C1: Actividad1 | F1: Nombre: | G1: prueba1 | N1: Actividad2 | Q1: Nombre: | R1: prueba2 | Y1: Actividad3 | AB1: Nombre: | AC1: prueba3 | AJ1: Actividad4 | AM1: Nombre: | AN1: prueba4 | AU1: Actividad5 | AX1: Nombre: | AY1: prueba5 | BF1: Actividad6 | BI1: Nombre: | BJ1: prueba6 | BQ1: Actividad7 | BT1: Nombre: | BU1: prueba7 | CB1: Actividad8 | CE1: Nombre: | CM1: Actividad9 | CP1: Nombre: | CX1: Actividad10 | DA1: Nombre: | DI1: Actividad11 | DL1: Nombre: | DT1: Actividad12 | DW1: Nombre: | EE1: Actividad13 | EH1: Nombre: | EP1: Actividad14 | ES1: Nombre: | FA1: Actividad15 | FD1: Nombre: | FL1: Actividad16 | FO1: Nombre: | FW1: Actividad17 | FZ1: Nombre: | GH1: Actividad18 | GK1: Nombre: | GS1: Actividad19 | GV1: Nombre: | HD1: Actividad20 | HG1: Nombre: | HO1: Actividad21 | HR1: Nombre: | HZ1: Actividad22 | IC1: Nombre: | IK1: Actividad23 | IN1: Nombre: | IV1: Actividad24 | IY1: Nombre: | JG1: Actividad25 | JJ1: Nombre: | JR1: Actividad26 | JU1: Nombre: | KC1: Actividad27 | KF1: Nombre: | KN1: Actividad28 | KQ1: Nombre: | KY1: Actividad29 | LB1: Nombre: | LJ1: Actividad30 | LM1: Nombre: | LW1: Suma ACT
C2: Control | D2: =SUM(D4:M4) -> 1 | F2: Tipo: | G2: Prueba escrita teórica | N2: Control | O2: =SUM(O4:X4) -> 1 | Q2: Tipo: | R2: Prueba escrita teórica | Y2: Control | Z2: =SUM(Z4:AI4) -> 1 | AB2: Tipo: | AC2: Prueba escrita teórica | AJ2: Control | AK2: =SUM(AK4:AT4) -> 1 | AM2: Tipo: | AN2: Prueba escrita teórica | AU2: Control | AV2: =SUM(AV4:BE4) -> 1 | AX2: Tipo: | AY2: Prueba escrita teórica | BF2: Control | BG2: =SUM(BG4:BP4) -> 1 | BI2: Tipo: | BJ2: Prueba escrita teórica | BQ2: Control | BR2: =SUM(BR4:CA4) -> 1 | BT2: Tipo: | BU2: Prueba escrita teórica | CB2: Control | CC2: =SUM(CC4:CL4) -> 0 | CE2: Tipo: | CM2: Control | CN2: =SUM(CN4:CW4) -> 0 | CP2: Tipo: | CX2: Control | CY2: =SUM(CY4:DH4) -> 0 | DA2: Tipo: | DI2: Control | DJ2: =SUM(DJ4:DS4) -> 0 | DL2: Tipo: | DT2: Control | DU2: =SUM(DU4:ED4) -> 0 | DW2: Tipo: | EE2: Control | EF2: =SUM(EF4:EO4) -> 0 | EH2: Tipo: | EP2: Control | EQ2: =SUM(EQ4:EZ4) -> 0 | ES2: Tipo: | FA2: Control | FB2: =SUM(FB4:FK4) -> 0 | FD2: Tipo: | FL2: Control | FM2: =SUM(FM4:FV4) -> 0 | FO2: Tipo: | FW2: Control | FX2: =SUM(FX4:GG4) -> 0 | FZ2: Tipo: | GH2: Control | GI2: =SUM(GI4:GR4) -> 0 | GK2: Tipo: | GS2: Control | GT2: =SUM(GT4:HC4) -> 0 | GV2: Tipo: | HD2: Control | HE2: =SUM(HE4:HN4) -> 0 | HG2: Tipo: | HO2: Control | HP2: =SUM(HP4:HY4) -> 0 | HR2: Tipo: | HZ2: Control | IA2: =SUM(IA4:IJ4) -> 0 | IC2: Tipo: | IK2: Control | IL2: =SUM(IL4:IU4) -> 0 | IN2: Tipo: | IV2: Control | IW2: =SUM(IW4:JF4) -> 0 | IY2: Tipo: | JG2: Control | JH2: =SUM(JH4:JQ4) -> 0 | JJ2: Tipo: | JR2: Control | JS2: =SUM(JS4:KB4) -> 0 | JU2: Tipo: | KC2: Control | KD2: =SUM(KD4:KM4) -> 0 | KF2: Tipo: | KN2: Control | KO2: =SUM(KO4:KX4) -> 0 | KQ2: Tipo: | KY2: Control | KZ2: =SUM(KZ4:LI4) -> 0 | LB2: Tipo: | LJ2: Control | LK2: =SUM(LK4:LT4) -> 0 | LM2: Tipo: | LW2: Control
C3: RA/Ej | D3: 1 | E3: 1 | F3: 1 | G3: 1 | H3: 1 | I3: 1 | J3: 1 | N3: RA/Ej | O3: 1 | P3: 1 | Q3: 2 | R3: 1 | S3: 1 | Y3: RA/Ej | Z3: 1 | AA3: 1 | AB3: 2 | AC3: 2 | AD3: 3 | AJ3: RA/Ej | AK3: 1 | AL3: 2 | AM3: 3 | AN3: 3 | AO3: 2 | AU3: RA/Ej | AV3: 1 | AW3: 2 | AX3: 3 | AY3: 3 | AZ3: 4 | BF3: RA/Ej | BG3: 1 | BH3: 2 | BI3: 3 | BJ3: 4 | BK3: 4 | BQ3: RA/Ej | BR3: 2 | BS3: 3 | BT3: 3 | BU3: 4 | BV3: 4 | CB3: RA/Ej | CM3: RA/Ej | CX3: RA/Ej | DI3: RA/Ej | DT3: RA/Ej | EE3: RA/Ej | EP3: RA/Ej | FA3: RA/Ej | FL3: RA/Ej | FW3: RA/Ej | GH3: RA/Ej | GS3: RA/Ej | HD3: RA/Ej | HO3: RA/Ej | HZ3: RA/Ej | IK3: RA/Ej | IV3: RA/Ej | JG3: RA/Ej | JR3: RA/Ej | KC3: RA/Ej | KN3: RA/Ej | KY3: RA/Ej | LJ3: RA/Ej
C4: Peso/Ej | D4: 0.15 | E4: 0.15 | F4: 0.2 | G4: 0.1 | H4: 0.15 | I4: 0.15 | J4: 0.1 | N4: Peso/Ej | O4: 0.2 | P4: 0.2 | Q4: 0.2 | R4: 0.2 | S4: 0.2 | Y4: Peso/Ej | Z4: 0.2 | AA4: 0.2 | AB4: 0.2 | AC4: 0.2 | AD4: 0.2 | AJ4: Peso/Ej | AK4: 0.2 | AL4: 0.2 | AM4: 0.2 | AN4: 0.2 | AO4: 0.2 | AU4: Peso/Ej | AV4: 0.1 | AW4: 0.2 | AX4: 0.2 | AY4: 0.3 | AZ4: 0.2 | BF4: Peso/Ej | BG4: 0.1 | BH4: 0.2 | BI4: 0.2 | BJ4: 0.2 | BK4: 0.3 | BQ4: Peso/Ej | BR4: 0.2 | BS4: 0.1 | BT4: 0.2 | BU4: 0.2 | BV4: 0.3 | CB4: Peso/Ej | CM4: Peso/Ej | CX4: Peso/Ej | DI4: Peso/Ej | DT4: Peso/Ej | EE4: Peso/Ej | EP4: Peso/Ej | FA4: Peso/Ej | FL4: Peso/Ej | FW4: Peso/Ej | GH4: Peso/Ej | GS4: Peso/Ej | HD4: Peso/Ej | HO4: Peso/Ej | HZ4: Peso/Ej | IK4: Peso/Ej | IV4: Peso/Ej | JG4: Peso/Ej | JR4: Peso/Ej | KC4: Peso/Ej | KN4: Peso/Ej | KY4: Peso/Ej | LJ4: Peso/Ej
C5: NOTA ACTIVIDAD | D5: Ejercicio1 | E5: Ejercicio2 | F5: Ejercicio3 | G5: Ejercicio4 | H5: Ejercicio5 | I5: Ejercicio6 | J5: Ejercicio7 | K5: Ejercicio8 | L5: Ejercicio9 | M5: Ejercicio10 | N5: NOTA ACTIVIDAD | O5: Ejercicio1 | P5: Ejercicio2 | Q5: Ejercicio3 | R5: Ejercicio4 | S5: Ejercicio5 | T5: Ejercicio6 | U5: Ejercicio7 | V5: Ejercicio8 | W5: Ejercicio9 | X5: Ejercicio10 | Y5: NOTA ACTIVIDAD | Z5: Ejercicio1 | AA5: Ejercicio2 | AB5: Ejercicio3 | AC5: Ejercicio4 | AD5: Ejercicio5 | AE5: Ejercicio6 | AF5: Ejercicio7 | AG5: Ejercicio8 | AH5: Ejercicio9 | AI5: Ejercicio10 | AJ5: NOTA ACTIVIDAD | AK5: Ejercicio1 | AL5: Ejercicio2 | AM5: Ejercicio3 | AN5: Ejercicio4 | AO5: Ejercicio5 | AP5: Ejercicio6 | AQ5: Ejercicio7 | AR5: Ejercicio8 | AS5: Ejercicio9 | AT5: Ejercicio10 | AU5: NOTA ACTIVIDAD | AV5: Ejercicio1 | AW5: Ejercicio2 | AX5: Ejercicio3 | AY5: Ejercicio4 | AZ5: Ejercicio5 | BA5: Ejercicio6 | BB5: Ejercicio7 | BC5: Ejercicio8 | BD5: Ejercicio9 | BE5: Ejercicio10 | BF5: NOTA ACTIVIDAD | BG5: Ejercicio1 | BH5: Ejercicio2 | BI5: Ejercicio3 | BJ5: Ejercicio4 | BK5: Ejercicio5 | BL5: Ejercicio6 | BM5: Ejercicio7 | BN5: Ejercicio8 | BO5: Ejercicio9 | BP5: Ejercicio10 | BQ5: NOTA ACTIVIDAD | BR5: Ejercicio1 | BS5: Ejercicio2 | BT5: Ejercicio3 | BU5: Ejercicio4 | BV5: Ejercicio5 | BW5: Ejercicio6 | BX5: Ejercicio7 | BY5: Ejercicio8 | BZ5: Ejercicio9 | CA5: Ejercicio10 | CB5: NOTA ACTIVIDAD | CC5: Ejercicio1 | CD5: Ejercicio2 | CE5: Ejercicio3 | CF5: Ejercicio4 | CG5: Ejercicio5 | CH5: Ejercicio6 | CI5: Ejercicio7 | CJ5: Ejercicio8 | CK5: Ejercicio9 | CL5: Ejercicio10 | CM5: NOTA ACTIVIDAD | CN5: Ejercicio1 | CO5: Ejercicio2 | CP5: Ejercicio3 | CQ5: Ejercicio4 | CR5: Ejercicio5 | CS5: Ejercicio6 | CT5: Ejercicio7 | CU5: Ejercicio8 | CV5: Ejercicio9 | CW5: Ejercicio10 | CX5: NOTA ACTIVIDAD | CY5: Ejercicio1 | CZ5: Ejercicio2 | DA5: Ejercicio3 | DB5: Ejercicio4 | DC5: Ejercicio5 | DD5: Ejercicio6 | DE5: Ejercicio7 | DF5: Ejercicio8 | DG5: Ejercicio9 | DH5: Ejercicio10 | DI5: NOTA ACTIVIDAD | DJ5: Ejercicio1 | DK5: Ejercicio2 | DL5: Ejercicio3 | DM5: Ejercicio4 | DN5: Ejercicio5 | DO5: Ejercicio6 | DP5: Ejercicio7 | DQ5: Ejercicio8 | DR5: Ejercicio9 | DS5: Ejercicio10 | DT5: NOTA ACTIVIDAD | DU5: Ejercicio1 | DV5: Ejercicio2 | DW5: Ejercicio3 | DX5: Ejercicio4 | DY5: Ejercicio5 | DZ5: Ejercicio6 | EA5: Ejercicio7 | EB5: Ejercicio8 | EC5: Ejercicio9 | ED5: Ejercicio10 | EE5: NOTA ACTIVIDAD | EF5: Ejercicio1 | EG5: Ejercicio2 | EH5: Ejercicio3 | EI5: Ejercicio4 | EJ5: Ejercicio5 | EK5: Ejercicio6 | EL5: Ejercicio7 | EM5: Ejercicio8 | EN5: Ejercicio9 | EO5: Ejercicio10 | EP5: NOTA ACTIVIDAD | EQ5: Ejercicio1 | ER5: Ejercicio2 | ES5: Ejercicio3 | ET5: Ejercicio4 | EU5: Ejercicio5 | EV5: Ejercicio6 | EW5: Ejercicio7 | EX5: Ejercicio8 | EY5: Ejercicio9 | EZ5: Ejercicio10 | FA5: NOTA ACTIVIDAD | FB5: Ejercicio1 | FC5: Ejercicio2 | FD5: Ejercicio3 | FE5: Ejercicio4 | FF5: Ejercicio5 | FG5: Ejercicio6 | FH5: Ejercicio7 | FI5: Ejercicio8 | FJ5: Ejercicio9 | FK5: Ejercicio10 | FL5: NOTA ACTIVIDAD | FM5: Ejercicio1 | FN5: Ejercicio2 | FO5: Ejercicio3 | FP5: Ejercicio4 | FQ5: Ejercicio5 | FR5: Ejercicio6 | FS5: Ejercicio7 | FT5: Ejercicio8 | FU5: Ejercicio9 | FV5: Ejercicio10 | FW5: NOTA ACTIVIDAD | FX5: Ejercicio1 | FY5: Ejercicio2 | FZ5: Ejercicio3 | GA5: Ejercicio4 | GB5: Ejercicio5 | GC5: Ejercicio6 | GD5: Ejercicio7 | GE5: Ejercicio8 | GF5: Ejercicio9 | GG5: Ejercicio10 | GH5: NOTA ACTIVIDAD | GI5: Ejercicio1 | GJ5: Ejercicio2 | GK5: Ejercicio3 | GL5: Ejercicio4 | GM5: Ejercicio5 | GN5: Ejercicio6 | GO5: Ejercicio7 | GP5: Ejercicio8 | GQ5: Ejercicio9 | GR5: Ejercicio10 | GS5: NOTA ACTIVIDAD | GT5: Ejercicio1 | GU5: Ejercicio2 | GV5: Ejercicio3 | GW5: Ejercicio4 | GX5: Ejercicio5 | GY5: Ejercicio6 | GZ5: Ejercicio7 | HA5: Ejercicio8 | HB5: Ejercicio9 | HC5: Ejercicio10 | HD5: NOTA ACTIVIDAD | HE5: Ejercicio1 | HF5: Ejercicio2 | HG5: Ejercicio3 | HH5: Ejercicio4 | HI5: Ejercicio5 | HJ5: Ejercicio6 | HK5: Ejercicio7 | HL5: Ejercicio8 | HM5: Ejercicio9 | HN5: Ejercicio10 | HO5: NOTA ACTIVIDAD | HP5: Ejercicio1 | HQ5: Ejercicio2 | HR5: Ejercicio3 | HS5: Ejercicio4 | HT5: Ejercicio5 | HU5: Ejercicio6 | HV5: Ejercicio7 | HW5: Ejercicio8 | HX5: Ejercicio9 | HY5: Ejercicio10 | HZ5: NOTA ACTIVIDAD | IA5: Ejercicio1 | IB5: Ejercicio2 | IC5: Ejercicio3 | ID5: Ejercicio4 | IE5: Ejercicio5 | IF5: Ejercicio6 | IG5: Ejercicio7 | IH5: Ejercicio8 | II5: Ejercicio9 | IJ5: Ejercicio10 | IK5: NOTA ACTIVIDAD | IL5: Ejercicio1 | IM5: Ejercicio2 | IN5: Ejercicio3 | IO5: Ejercicio4 | IP5: Ejercicio5 | IQ5: Ejercicio6 | IR5: Ejercicio7 | IS5: Ejercicio8 | IT5: Ejercicio9 | IU5: Ejercicio10 | IV5: NOTA ACTIVIDAD | IW5: Ejercicio1 | IX5: Ejercicio2 | IY5: Ejercicio3 | IZ5: Ejercicio4 | JA5: Ejercicio5 | JB5: Ejercicio6 | JC5: Ejercicio7 | JD5: Ejercicio8 | JE5: Ejercicio9 | JF5: Ejercicio10 | JG5: NOTA ACTIVIDAD | JH5: Ejercicio1 | JI5: Ejercicio2 | JJ5: Ejercicio3 | JK5: Ejercicio4 | JL5: Ejercicio5 | JM5: Ejercicio6 | JN5: Ejercicio7 | JO5: Ejercicio8 | JP5: Ejercicio9 | JQ5: Ejercicio10 | JR5: NOTA ACTIVIDAD | JS5: Ejercicio1 | JT5: Ejercicio2 | JU5: Ejercicio3 | JV5: Ejercicio4 | JW5: Ejercicio5 | JX5: Ejercicio6 | JY5: Ejercicio7 | JZ5: Ejercicio8 | KA5: Ejercicio9 | KB5: Ejercicio10 | KC5: NOTA ACTIVIDAD | KD5: Ejercicio1 | KE5: Ejercicio2 | KF5: Ejercicio3 | KG5: Ejercicio4 | KH5: Ejercicio5 | KI5: Ejercicio6 | KJ5: Ejercicio7 | KK5: Ejercicio8 | KL5: Ejercicio9 | KM5: Ejercicio10 | KN5: NOTA ACTIVIDAD | KO5: Ejercicio1 | KP5: Ejercicio2 | KQ5: Ejercicio3 | KR5: Ejercicio4 | KS5: Ejercicio5 | KT5: Ejercicio6 | KU5: Ejercicio7 | KV5: Ejercicio8 | KW5: Ejercicio9 | KX5: Ejercicio10 | KY5: NOTA ACTIVIDAD | KZ5: Ejercicio1 | LA5: Ejercicio2 | LB5: Ejercicio3 | LC5: Ejercicio4 | LD5: Ejercicio5 | LE5: Ejercicio6 | LF5: Ejercicio7 | LG5: Ejercicio8 | LH5: Ejercicio9 | LI5: Ejercicio10 | LJ5: NOTA ACTIVIDAD | LK5: Ejercicio1 | LL5: Ejercicio2 | LM5: Ejercicio3 | LN5: Ejercicio4 | LO5: Ejercicio5 | LP5: Ejercicio6 | LQ5: Ejercicio7 | LR5: Ejercicio8 | LS5: Ejercicio9 | LT5: Ejercicio10 | LX5: RA1 | LY5: RA2 | LZ5: RA3 | MA5: RA4 | MB5: RA5 | MC5: RA6 | MD5: RA7 | ME5: RA8 | MF5: RA9 | MG5: RA10
A6: 1 | B6: ='Datos Iniciales'!T9 -> Alumno1 | C6: =SUMPRODUCT(D$4:M$4,D6:M6) -> 6.9 | D6: 8 | E6: 5 | F6: 7 | G6: 4 | H6: 9 | I6: 8 | J6: 6 | N6: =SUMPRODUCT(O$4:X$4,O6:X6) -> 7 | O6: 6 | P6: 7 | Q6: 8 | R6: 9 | S6: 5 | Y6: =SUMPRODUCT(Z$4:AI$4,Z6:AI6) -> 7 | Z6: 6 | AA6: 7 | AB6: 8 | AC6: 9 | AD6: 5 | AJ6: =SUMPRODUCT(AK$4:AT$4,AK6:AT6) -> 7 | AK6: 6 | AL6: 7 | AM6: 8 | AN6: 9 | AO6: 5 | AU6: =SUMPRODUCT(AV$4:BE$4,AV6:BE6) -> 6.2 | AV6: 8 | AW6: 5 | AX6: 7 | AY6: 4 | AZ6: 9 | BF6: =SUMPRODUCT(BG$4:BP$4,BG6:BP6) -> 6.7 | BG6: 8 | BH6: 5 | BI6: 7 | BJ6: 4 | BK6: 9 | BQ6: =SUMPRODUCT(BR$4:CA$4,BR6:CA6) -> 4.5 | BR6: 4 | BS6: 3 | BT6: 5 | BU6: 6 | BV6: 4 | CB6: =SUMPRODUCT(CC$4:CL$4,CC6:CL6) -> 0 | CM6: =SUMPRODUCT(CN$4:CW$4,CN6:CW6) -> 0 | CX6: =SUMPRODUCT(CY$4:DH$4,CY6:DH6) -> 0 | DI6: =SUMPRODUCT(DJ$4:DS$4,DJ6:DS6) -> 0 | DT6: =SUMPRODUCT(DU$4:ED$4,DU6:ED6) -> 0 | EE6: =SUMPRODUCT(EF$4:EO$4,EF6:EO6) -> 0 | EP6: =SUMPRODUCT(EQ$4:EZ$4,EQ6:EZ6) -> 0 | FA6: =SUMPRODUCT(FB$4:FK$4,FB6:FK6) -> 0 | FL6: =SUMPRODUCT(FM$4:FV$4,FM6:FV6) -> 0 | FW6: =SUMPRODUCT(FX$4:GG$4,FX6:GG6) -> 0 | GH6: =SUMPRODUCT(GI$4:GR$4,GI6:GR6) -> 0 | GS6: =SUMPRODUCT(GT$4:HC$4,GT6:HC6) -> 0 | HD6: =SUMPRODUCT(HE$4:HN$4,HE6:HN6) -> 0 | HO6: =SUMPRODUCT(HP$4:HY$4,HP6:HY6) -> 0 | HZ6: =SUMPRODUCT(IA$4:IJ$4,IA6:IJ6) -> 0 | IK6: =SUMPRODUCT(IL$4:IU$4,IL6:IU6) -> 0 | IV6: =SUMPRODUCT(IW$4:JF$4,IW6:JF6) -> 0 | JG6: =SUMPRODUCT(JH$4:JQ$4,JH6:JQ6) -> 0 | JR6: =SUMPRODUCT(JS$4:KB$4,JS6:KB6) -> 0 | KC6: =SUMPRODUCT(KD$4:KM$4,KD6:KM6) -> 0 | KN6: =SUMPRODUCT(KO$4:KX$4,KO6:KX6) -> 0 | KY6: =SUMPRODUCT(KZ$4:LI$4,KZ6:LI6) -> 0 | LJ6: =SUMPRODUCT(LK$4:LT$4,LK6:LT6) -> 0 | LX6: =D160+O160+Z160+AK160+AV160+BG160+BR160+CC160+CN160+CY160+DJ160+DU160+EF160+EQ160+FB160+FM160+FX160+GI160+GT160+HE160+HP160+IA160+IL160+IW160+JH160+JS160+KD160+KO160+KZ160+LK160 -> 6.825 | LY6: =E160+P160+AA160+AL160+AW160+BH160+BS160+CD160+CO160+CZ160+DK160+DV160+EG160+ER160+FC160+FN160+FY160+GJ160+GU160+HF160+HQ160+IB160+IM160+IX160+JI160+JT160+KE160+KP160+LA160+LL160 -> 6.55 | LZ6: =F160+Q160+AB160+AM160+AX160+BI160+BT160+CE160+CP160+DA160+DL160+DW160+EH160+ES160+FD160+FO160+FZ160+GK160+GV160+HG160+HR160+IC160+IN160+IY160+JJ160+JU160+KF160+KQ160+LB160+LM160 -> 6.385 | MA6: =G160+R160+AC160+AN160+AY160+BJ160+BU160+CF160+CQ160+DB160+DM160+DX160+EI160+ET160+FE160+FP160+GA160+GL160+GW160+HH160+HS160+ID160+IO160+IZ160+JK160+JV160+KG160+KR160+LC160+LN160 -> 6.1 | MB6: =H160+S160+AD160+AO160+AZ160+BK160+BV160+CG160+CR160+DC160+DN160+DY160+EJ160+EU160+FF160+FQ160+GB160+GM160+GX160+HI160+HT160+IE160+IP160+JA160+JL160+JW160+KH160+KS160+LD160+LO160 -> 0 | MC6: =I160+T160+AE160+AP160+BA160+BL160+BW160+CH160+CS160+DD160+DO160+DZ160+EK160+EV160+FG160+FR160+GC160+GN160+GY160+HJ160+HU160+IF160+IQ160+JB160+JM160+JX160+KI160+KT160+LE160+LP160 -> 0 | MD6: =J160+U160+AF160+AQ160+BB160+BM160+BX160+CI160+CT160+DE160+DP160+EA160+EL160+EW160+FH160+FS160+GD160+GO160+GZ160+HK160+HV160+IG160+IR160+JC160+JN160+JY160+KJ160+KU160+LF160+LQ160 -> 0 | ME6: =K160+V160+AG160+AR160+BC160+BN160+BY160+CJ160+CU160+DF160+DQ160+EB160+EM160+EX160+FI160+FT160+GE160+GP160+HA160+HL160+HW160+IH160+IS160+JD160+JO160+JZ160+KK160+KV160+LG160+LR160 -> 0 | ... MG6: =M160+X160+AI160+AT160+BE160+BP160+CA160+CL160+CW160+DH160+DS160+ED160+EO160+EZ160+FK160+FV160+GG160+GR160+HC160+HN160+HY160+IJ160+IU160+JF160+JQ160+KB160+KM160+KX160+LI160+LT160 -> 0
A7: 2 | B7: ='Datos Iniciales'!T10 -> Alumno2 | C7: =SUMPRODUCT(D$4:M$4,D7:M7) -> 5 | D7: 5 | E7: 5 | F7: 5 | G7: 5 | H7: 5 | I7: 5 | J7: 5 | N7: =SUMPRODUCT(O$4:X$4,O7:X7) -> 5 | O7: 5 | P7: 5 | Q7: 5 | R7: 5 | S7: 5 | Y7: =SUMPRODUCT(Z$4:AI$4,Z7:AI7) -> 5 | Z7: 5 | AA7: 5 | AB7: 5 | AC7: 5 | AD7: 5 | AJ7: =SUMPRODUCT(AK$4:AT$4,AK7:AT7) -> 5 | AK7: 5 | AL7: 5 | AM7: 5 | AN7: 5 | AO7: 5 | AU7: =SUMPRODUCT(AV$4:BE$4,AV7:BE7) -> 5 | AV7: 5 | AW7: 5 | AX7: 5 | AY7: 5 | AZ7: 5 | BF7: =SUMPRODUCT(BG$4:BP$4,BG7:BP7) -> 5 | BG7: 5 | BH7: 5 | BI7: 5 | BJ7: 5 | BK7: 5 | BQ7: =SUMPRODUCT(BR$4:CA$4,BR7:CA7) -> 3.6 | BR7: 3 | BS7: 3 | BT7: 2 | BU7: 4 | BV7: 5 | CB7: =SUMPRODUCT(CC$4:CL$4,CC7:CL7) -> 0 | CM7: =SUMPRODUCT(CN$4:CW$4,CN7:CW7) -> 0 | CX7: =SUMPRODUCT(CY$4:DH$4,CY7:DH7) -> 0 | DI7: =SUMPRODUCT(DJ$4:DS$4,DJ7:DS7) -> 0 | DT7: =SUMPRODUCT(DU$4:ED$4,DU7:ED7) -> 0 | EE7: =SUMPRODUCT(EF$4:EO$4,EF7:EO7) -> 0 | EP7: =SUMPRODUCT(EQ$4:EZ$4,EQ7:EZ7) -> 0 | FA7: =SUMPRODUCT(FB$4:FK$4,FB7:FK7) -> 0 | FL7: =SUMPRODUCT(FM$4:FV$4,FM7:FV7) -> 0 | FW7: =SUMPRODUCT(FX$4:GG$4,FX7:GG7) -> 0 | GH7: =SUMPRODUCT(GI$4:GR$4,GI7:GR7) -> 0 | GS7: =SUMPRODUCT(GT$4:HC$4,GT7:HC7) -> 0 | HD7: =SUMPRODUCT(HE$4:HN$4,HE7:HN7) -> 0 | HO7: =SUMPRODUCT(HP$4:HY$4,HP7:HY7) -> 0 | HZ7: =SUMPRODUCT(IA$4:IJ$4,IA7:IJ7) -> 0 | IK7: =SUMPRODUCT(IL$4:IU$4,IL7:IU7) -> 0 | IV7: =SUMPRODUCT(IW$4:JF$4,IW7:JF7) -> 0 | JG7: =SUMPRODUCT(JH$4:JQ$4,JH7:JQ7) -> 0 | JR7: =SUMPRODUCT(JS$4:KB$4,JS7:KB7) -> 0 | KC7: =SUMPRODUCT(KD$4:KM$4,KD7:KM7) -> 0 | KN7: =SUMPRODUCT(KO$4:KX$4,KO7:KX7) -> 0 | KY7: =SUMPRODUCT(KZ$4:LI$4,KZ7:LI7) -> 0 | LJ7: =SUMPRODUCT(LK$4:LT$4,LK7:LT7) -> 0 | LX7: =D161+O161+Z161+AK161+AV161+BG161+BR161+CC161+CN161+CY161+DJ161+DU161+EF161+EQ161+FB161+FM161+FX161+GI161+GT161+HE161+HP161+IA161+IL161+IW161+JH161+JS161+KD161+KO161+KZ161+LK161 -> 5 | LY7: =E161+P161+AA161+AL161+AW161+BH161+BS161+CD161+CO161+CZ161+DK161+DV161+EG161+ER161+FC161+FN161+FY161+GJ161+GU161+HF161+HQ161+IB161+IM161+IX161+JI161+JT161+KE161+KP161+LA161+LL161 -> 4.9 | LZ7: =F161+Q161+AB161+AM161+AX161+BI161+BT161+CE161+CP161+DA161+DL161+DW161+EH161+ES161+FD161+FO161+FZ161+GK161+GV161+HG161+HR161+IC161+IN161+IY161+JJ161+JU161+KF161+KQ161+LB161+LM161 -> 4.6 | MA7: =G161+R161+AC161+AN161+AY161+BJ161+BU161+CF161+CQ161+DB161+DM161+DX161+EI161+ET161+FE161+FP161+GA161+GL161+GW161+HH161+HS161+ID161+IO161+IZ161+JK161+JV161+KG161+KR161+LC161+LN161 -> 4.8 | MB7: =H161+S161+AD161+AO161+AZ161+BK161+BV161+CG161+CR161+DC161+DN161+DY161+EJ161+EU161+FF161+FQ161+GB161+GM161+GX161+HI161+HT161+IE161+IP161+JA161+JL161+JW161+KH161+KS161+LD161+LO161 -> 0 | MC7: =I161+T161+AE161+AP161+BA161+BL161+BW161+CH161+CS161+DD161+DO161+DZ161+EK161+EV161+FG161+FR161+GC161+GN161+GY161+HJ161+HU161+IF161+IQ161+JB161+JM161+JX161+KI161+KT161+LE161+LP161 -> 0 | MD7: =J161+U161+AF161+AQ161+BB161+BM161+BX161+CI161+CT161+DE161+DP161+EA161+EL161+EW161+FH161+FS161+GD161+GO161+GZ161+HK161+HV161+IG161+IR161+JC161+JN161+JY161+KJ161+KU161+LF161+LQ161 -> 0 | ME7: =K161+V161+AG161+AR161+BC161+BN161+BY161+CJ161+CU161+DF161+DQ161+EB161+EM161+EX161+FI161+FT161+GE161+GP161+HA161+HL161+HW161+IH161+IS161+JD161+JO161+JZ161+KK161+KV161+LG161+LR161 -> 0 | ... MG7: =M161+X161+AI161+AT161+BE161+BP161+CA161+CL161+CW161+DH161+DS161+ED161+EO161+EZ161+FK161+FV161+GG161+GR161+HC161+HN161+HY161+IJ161+IU161+JF161+JQ161+KB161+KM161+KX161+LI161+LT161 -> 0
A8: 3 | B8: ='Datos Iniciales'!T11 -> Alumno3 | C8: =SUMPRODUCT(D$4:M$4,D8:M8) -> 5.3 | D8: 6 | E8: 7 | F8: 4 | G8: 4 | H8: 5 | I8: 6 | J8: 5 | N8: =SUMPRODUCT(O$4:X$4,O8:X8) -> 4.6 | O8: 5 | P8: 6 | Q8: 3 | R8: 4 | S8: 5 | Y8: =SUMPRODUCT(Z$4:AI$4,Z8:AI8) -> 4.6 | Z8: 5 | AA8: 6 | AB8: 3 | AC8: 4 | AD8: 5 | AJ8: =SUMPRODUCT(AK$4:AT$4,AK8:AT8) -> 4.6 | AK8: 5 | AL8: 6 | AM8: 3 | AN8: 4 | AO8: 5 | AU8: =SUMPRODUCT(AV$4:BE$4,AV8:BE8) -> 5 | AV8: 6 | AW8: 7 | AX8: 4 | AY8: 4 | AZ8: 5 | BF8: =SUMPRODUCT(BG$4:BP$4,BG8:BP8) -> 5.1 | BG8: 6 | BH8: 7 | BI8: 4 | BJ8: 4 | BK8: 5 | BQ8: =SUMPRODUCT(BR$4:CA$4,BR8:CA8) -> 9.5 | BR8: 9 | BS8: 10 | BT8: 10 | BU8: 10 | BV8: 9 | CB8: =SUMPRODUCT(CC$4:CL$4,CC8:CL8) -> 0 | CM8: =SUMPRODUCT(CN$4:CW$4,CN8:CW8) -> 0 | CX8: =SUMPRODUCT(CY$4:DH$4,CY8:DH8) -> 0 | DI8: =SUMPRODUCT(DJ$4:DS$4,DJ8:DS8) -> 0 | DT8: =SUMPRODUCT(DU$4:ED$4,DU8:ED8) -> 0 | EE8: =SUMPRODUCT(EF$4:EO$4,EF8:EO8) -> 0 | EP8: =SUMPRODUCT(EQ$4:EZ$4,EQ8:EZ8) -> 0 | FA8: =SUMPRODUCT(FB$4:FK$4,FB8:FK8) -> 0 | FL8: =SUMPRODUCT(FM$4:FV$4,FM8:FV8) -> 0 | FW8: =SUMPRODUCT(FX$4:GG$4,FX8:GG8) -> 0 | GH8: =SUMPRODUCT(GI$4:GR$4,GI8:GR8) -> 0 | GS8: =SUMPRODUCT(GT$4:HC$4,GT8:HC8) -> 0 | HD8: =SUMPRODUCT(HE$4:HN$4,HE8:HN8) -> 0 | HO8: =SUMPRODUCT(HP$4:HY$4,HP8:HY8) -> 0 | HZ8: =SUMPRODUCT(IA$4:IJ$4,IA8:IJ8) -> 0 | IK8: =SUMPRODUCT(IL$4:IU$4,IL8:IU8) -> 0 | IV8: =SUMPRODUCT(IW$4:JF$4,IW8:JF8) -> 0 | JG8: =SUMPRODUCT(JH$4:JQ$4,JH8:JQ8) -> 0 | JR8: =SUMPRODUCT(JS$4:KB$4,JS8:KB8) -> 0 | KC8: =SUMPRODUCT(KD$4:KM$4,KD8:KM8) -> 0 | KN8: =SUMPRODUCT(KO$4:KX$4,KO8:KX8) -> 0 | KY8: =SUMPRODUCT(KZ$4:LI$4,KZ8:LI8) -> 0 | LJ8: =SUMPRODUCT(LK$4:LT$4,LK8:LT8) -> 0 | LX8: =D162+O162+Z162+AK162+AV162+BG162+BR162+CC162+CN162+CY162+DJ162+DU162+EF162+EQ162+FB162+FM162+FX162+GI162+GT162+HE162+HP162+IA162+IL162+IW162+JH162+JS162+KD162+KO162+KZ162+LK162 -> 5.375 | LY8: =E162+P162+AA162+AL162+AW162+BH162+BS162+CD162+CO162+CZ162+DK162+DV162+EG162+ER162+FC162+FN162+FY162+GJ162+GU162+HF162+HQ162+IB162+IM162+IX162+JI162+JT162+KE162+KP162+LA162+LL162 -> 5.15 | LZ8: =F162+Q162+AB162+AM162+AX162+BI162+BT162+CE162+CP162+DA162+DL162+DW162+EH162+ES162+FD162+FO162+FZ162+GK162+GV162+HG162+HR162+IC162+IN162+IY162+JJ162+JU162+KF162+KQ162+LB162+LM162 -> 4.825 | MA8: =G162+R162+AC162+AN162+AY162+BJ162+BU162+CF162+CQ162+DB162+DM162+DX162+EI162+ET162+FE162+FP162+GA162+GL162+GW162+HH162+HS162+ID162+IO162+IZ162+JK162+JV162+KG162+KR162+LC162+LN162 -> 7.04 | MB8: =H162+S162+AD162+AO162+AZ162+BK162+BV162+CG162+CR162+DC162+DN162+DY162+EJ162+EU162+FF162+FQ162+GB162+GM162+GX162+HI162+HT162+IE162+IP162+JA162+JL162+JW162+KH162+KS162+LD162+LO162 -> 0 | MC8: =I162+T162+AE162+AP162+BA162+BL162+BW162+CH162+CS162+DD162+DO162+DZ162+EK162+EV162+FG162+FR162+GC162+GN162+GY162+HJ162+HU162+IF162+IQ162+JB162+JM162+JX162+KI162+KT162+LE162+LP162 -> 0 | MD8: =J162+U162+AF162+AQ162+BB162+BM162+BX162+CI162+CT162+DE162+DP162+EA162+EL162+EW162+FH162+FS162+GD162+GO162+GZ162+HK162+HV162+IG162+IR162+JC162+JN162+JY162+KJ162+KU162+LF162+LQ162 -> 0 | ME8: =K162+V162+AG162+AR162+BC162+BN162+BY162+CJ162+CU162+DF162+DQ162+EB162+EM162+EX162+FI162+FT162+GE162+GP162+HA162+HL162+HW162+IH162+IS162+JD162+JO162+JZ162+KK162+KV162+LG162+LR162 -> 0 | ... MG8: =M162+X162+AI162+AT162+BE162+BP162+CA162+CL162+CW162+DH162+DS162+ED162+EO162+EZ162+FK162+FV162+GG162+GR162+HC162+HN162+HY162+IJ162+IU162+JF162+JQ162+KB162+KM162+KX162+LI162+LT162 -> 0
A9: 4 | B9: ='Datos Iniciales'!T12 -> Alumno4 | C9: =SUMPRODUCT(D$4:M$4,D9:M9) -> 4.1 | D9: 4 | E9: 3 | F9: 5 | G9: 6 | H9: 4 | I9: 3 | J9: 4 | N9: =SUMPRODUCT(O$4:X$4,O9:X9) -> 5 | O9: 5 | P9: 5 | Q9: 5 | R9: 5 | S9: 5 | Y9: =SUMPRODUCT(Z$4:AI$4,Z9:AI9) -> 5 | Z9: 5 | AA9: 5 | AB9: 5 | AC9: 5 | AD9: 5 | AJ9: =SUMPRODUCT(AK$4:AT$4,AK9:AT9) -> 5 | AK9: 5 | AL9: 5 | AM9: 5 | AN9: 5 | AO9: 5 | AU9: =SUMPRODUCT(AV$4:BE$4,AV9:BE9) -> 4.6 | AV9: 4 | AW9: 3 | AX9: 5 | AY9: 6 | AZ9: 4 | BF9: =SUMPRODUCT(BG$4:BP$4,BG9:BP9) -> 4.4 | BG9: 4 | BH9: 3 | BI9: 5 | BJ9: 6 | BK9: 4 | BQ9: =SUMPRODUCT(BR$4:CA$4,BR9:CA9) -> 9 | BR9: 9 | BS9: 9 | BT9: 9 | BU9: 9 | BV9: 9 | CB9: =SUMPRODUCT(CC$4:CL$4,CC9:CL9) -> 0 | CM9: =SUMPRODUCT(CN$4:CW$4,CN9:CW9) -> 0 | CX9: =SUMPRODUCT(CY$4:DH$4,CY9:DH9) -> 0 | DI9: =SUMPRODUCT(DJ$4:DS$4,DJ9:DS9) -> 0 | DT9: =SUMPRODUCT(DU$4:ED$4,DU9:ED9) -> 0 | EE9: =SUMPRODUCT(EF$4:EO$4,EF9:EO9) -> 0 | EP9: =SUMPRODUCT(EQ$4:EZ$4,EQ9:EZ9) -> 0 | FA9: =SUMPRODUCT(FB$4:FK$4,FB9:FK9) -> 0 | FL9: =SUMPRODUCT(FM$4:FV$4,FM9:FV9) -> 0 | FW9: =SUMPRODUCT(FX$4:GG$4,FX9:GG9) -> 0 | GH9: =SUMPRODUCT(GI$4:GR$4,GI9:GR9) -> 0 | GS9: =SUMPRODUCT(GT$4:HC$4,GT9:HC9) -> 0 | HD9: =SUMPRODUCT(HE$4:HN$4,HE9:HN9) -> 0 | HO9: =SUMPRODUCT(HP$4:HY$4,HP9:HY9) -> 0 | HZ9: =SUMPRODUCT(IA$4:IJ$4,IA9:IJ9) -> 0 | IK9: =SUMPRODUCT(IL$4:IU$4,IL9:IU9) -> 0 | IV9: =SUMPRODUCT(IW$4:JF$4,IW9:JF9) -> 0 | JG9: =SUMPRODUCT(JH$4:JQ$4,JH9:JQ9) -> 0 | JR9: =SUMPRODUCT(JS$4:KB$4,JS9:KB9) -> 0 | KC9: =SUMPRODUCT(KD$4:KM$4,KD9:KM9) -> 0 | KN9: =SUMPRODUCT(KO$4:KX$4,KO9:KX9) -> 0 | KY9: =SUMPRODUCT(KZ$4:LI$4,KZ9:LI9) -> 0 | LJ9: =SUMPRODUCT(LK$4:LT$4,LK9:LT9) -> 0 | LX9: =D163+O163+Z163+AK163+AV163+BG163+BR163+CC163+CN163+CY163+DJ163+DU163+EF163+EQ163+FB163+FM163+FX163+GI163+GT163+HE163+HP163+IA163+IL163+IW163+JH163+JS163+KD163+KO163+KZ163+LK163 -> 4.625 | LY9: =E163+P163+AA163+AL163+AW163+BH163+BS163+CD163+CO163+CZ163+DK163+DV163+EG163+ER163+FC163+FN163+FY163+GJ163+GU163+HF163+HQ163+IB163+IM163+IX163+JI163+JT163+KE163+KP163+LA163+LL163 -> 4.7 | LZ9: =F163+Q163+AB163+AM163+AX163+BI163+BT163+CE163+CP163+DA163+DL163+DW163+EH163+ES163+FD163+FO163+FZ163+GK163+GV163+HG163+HR163+IC163+IN163+IY163+JJ163+JU163+KF163+KQ163+LB163+LM163 -> 5.78 | MA9: =G163+R163+AC163+AN163+AY163+BJ163+BU163+CF163+CQ163+DB163+DM163+DX163+EI163+ET163+FE163+FP163+GA163+GL163+GW163+HH163+HS163+ID163+IO163+IZ163+JK163+JV163+KG163+KR163+LC163+LN163 -> 6.82 | MB9: =H163+S163+AD163+AO163+AZ163+BK163+BV163+CG163+CR163+DC163+DN163+DY163+EJ163+EU163+FF163+FQ163+GB163+GM163+GX163+HI163+HT163+IE163+IP163+JA163+JL163+JW163+KH163+KS163+LD163+LO163 -> 0 | MC9: =I163+T163+AE163+AP163+BA163+BL163+BW163+CH163+CS163+DD163+DO163+DZ163+EK163+EV163+FG163+FR163+GC163+GN163+GY163+HJ163+HU163+IF163+IQ163+JB163+JM163+JX163+KI163+KT163+LE163+LP163 -> 0 | MD9: =J163+U163+AF163+AQ163+BB163+BM163+BX163+CI163+CT163+DE163+DP163+EA163+EL163+EW163+FH163+FS163+GD163+GO163+GZ163+HK163+HV163+IG163+IR163+JC163+JN163+JY163+KJ163+KU163+LF163+LQ163 -> 0 | ME9: =K163+V163+AG163+AR163+BC163+BN163+BY163+CJ163+CU163+DF163+DQ163+EB163+EM163+EX163+FI163+FT163+GE163+GP163+HA163+HL163+HW163+IH163+IS163+JD163+JO163+JZ163+KK163+KV163+LG163+LR163 -> 0 | ... MG9: =M163+X163+AI163+AT163+BE163+BP163+CA163+CL163+CW163+DH163+DS163+ED163+EO163+EZ163+FK163+FV163+GG163+GR163+HC163+HN163+HY163+IJ163+IU163+JF163+JQ163+KB163+KM163+KX163+LI163+LT163 -> 0
A10: 5 | B10: ='Datos Iniciales'!T13 -> Alumno5 | C10: =SUMPRODUCT(D$4:M$4,D10:M10) -> 3.35 | D10: 3 | E10: 3 | F10: 2 | G10: 4 | H10: 5 | I10: 4 | J10: 3 | N10: =SUMPRODUCT(O$4:X$4,O10:X10) -> 9 | O10: 9 | P10: 9 | Q10: 9 | R10: 9 | S10: 9 | Y10: =SUMPRODUCT(Z$4:AI$4,Z10:AI10) -> 9 | Z10: 9 | AA10: 9 | AB10: 9 | AC10: 9 | AD10: 9 | AJ10: =SUMPRODUCT(AK$4:AT$4,AK10:AT10) -> 9 | AK10: 9 | AL10: 9 | AM10: 9 | AN10: 9 | AO10: 9 | AU10: =SUMPRODUCT(AV$4:BE$4,AV10:BE10) -> 3.5 | AV10: 3 | AW10: 3 | AX10: 2 | AY10: 4 | AZ10: 5 | BF10: =SUMPRODUCT(BG$4:BP$4,BG10:BP10) -> 3.6 | BG10: 3 | BH10: 3 | BI10: 2 | BJ10: 4 | BK10: 5 | BQ10: =SUMPRODUCT(BR$4:CA$4,BR10:CA10) -> 9.7 | BR10: 10 | BS10: 9 | BT10: 10 | BU10: 9 | BV10: 10 | CB10: =SUMPRODUCT(CC$4:CL$4,CC10:CL10) -> 0 | CM10: =SUMPRODUCT(CN$4:CW$4,CN10:CW10) -> 0 | CX10: =SUMPRODUCT(CY$4:DH$4,CY10:DH10) -> 0 | DI10: =SUMPRODUCT(DJ$4:DS$4,DJ10:DS10) -> 0 | DT10: =SUMPRODUCT(DU$4:ED$4,DU10:ED10) -> 0 | EE10: =SUMPRODUCT(EF$4:EO$4,EF10:EO10) -> 0 | EP10: =SUMPRODUCT(EQ$4:EZ$4,EQ10:EZ10) -> 0 | FA10: =SUMPRODUCT(FB$4:FK$4,FB10:FK10) -> 0 | FL10: =SUMPRODUCT(FM$4:FV$4,FM10:FV10) -> 0 | FW10: =SUMPRODUCT(FX$4:GG$4,FX10:GG10) -> 0 | GH10: =SUMPRODUCT(GI$4:GR$4,GI10:GR10) -> 0 | GS10: =SUMPRODUCT(GT$4:HC$4,GT10:HC10) -> 0 | HD10: =SUMPRODUCT(HE$4:HN$4,HE10:HN10) -> 0 | HO10: =SUMPRODUCT(HP$4:HY$4,HP10:HY10) -> 0 | HZ10: =SUMPRODUCT(IA$4:IJ$4,IA10:IJ10) -> 0 | IK10: =SUMPRODUCT(IL$4:IU$4,IL10:IU10) -> 0 | IV10: =SUMPRODUCT(IW$4:JF$4,IW10:JF10) -> 0 | JG10: =SUMPRODUCT(JH$4:JQ$4,JH10:JQ10) -> 0 | JR10: =SUMPRODUCT(JS$4:KB$4,JS10:KB10) -> 0 | KC10: =SUMPRODUCT(KD$4:KM$4,KD10:KM10) -> 0 | KN10: =SUMPRODUCT(KO$4:KX$4,KO10:KX10) -> 0 | KY10: =SUMPRODUCT(KZ$4:LI$4,KZ10:LI10) -> 0 | LJ10: =SUMPRODUCT(LK$4:LT$4,LK10:LT10) -> 0 | LX10: =D164+O164+Z164+AK164+AV164+BG164+BR164+CC164+CN164+CY164+DJ164+DU164+EF164+EQ164+FB164+FM164+FX164+GI164+GT164+HE164+HP164+IA164+IL164+IW164+JH164+JS164+KD164+KO164+KZ164+LK164 -> 6.6875 | LY10: =E164+P164+AA164+AL164+AW164+BH164+BS164+CD164+CO164+CZ164+DK164+DV164+EG164+ER164+FC164+FN164+FY164+GJ164+GU164+HF164+HQ164+IB164+IM164+IX164+JI164+JT164+KE164+KP164+LA164+LL164 -> 7.55 | LZ10: =F164+Q164+AB164+AM164+AX164+BI164+BT164+CE164+CP164+DA164+DL164+DW164+EH164+ES164+FD164+FO164+FZ164+GK164+GV164+HG164+HR164+IC164+IN164+IY164+JJ164+JU164+KF164+KQ164+LB164+LM164 -> 6.66 | MA10: =G164+R164+AC164+AN164+AY164+BJ164+BU164+CF164+CQ164+DB164+DM164+DX164+EI164+ET164+FE164+FP164+GA164+GL164+GW164+HH164+HS164+ID164+IO164+IZ164+JK164+JV164+KG164+KR164+LC164+LN164 -> 7.14 | MB10: =H164+S164+AD164+AO164+AZ164+BK164+BV164+CG164+CR164+DC164+DN164+DY164+EJ164+EU164+FF164+FQ164+GB164+GM164+GX164+HI164+HT164+IE164+IP164+JA164+JL164+JW164+KH164+KS164+LD164+LO164 -> 0 | MC10: =I164+T164+AE164+AP164+BA164+BL164+BW164+CH164+CS164+DD164+DO164+DZ164+EK164+EV164+FG164+FR164+GC164+GN164+GY164+HJ164+HU164+IF164+IQ164+JB164+JM164+JX164+KI164+KT164+LE164+LP164 -> 0 | MD10: =J164+U164+AF164+AQ164+BB164+BM164+BX164+CI164+CT164+DE164+DP164+EA164+EL164+EW164+FH164+FS164+GD164+GO164+GZ164+HK164+HV164+IG164+IR164+JC164+JN164+JY164+KJ164+KU164+LF164+LQ164 -> 0 | ME10: =K164+V164+AG164+AR164+BC164+BN164+BY164+CJ164+CU164+DF164+DQ164+EB164+EM164+EX164+FI164+FT164+GE164+GP164+HA164+HL164+HW164+IH164+IS164+JD164+JO164+JZ164+KK164+KV164+LG164+LR164 -> 0 | ... MG10: =M164+X164+AI164+AT164+BE164+BP164+CA164+CL164+CW164+DH164+DS164+ED164+EO164+EZ164+FK164+FV164+GG164+GR164+HC164+HN164+HY164+IJ164+IU164+JF164+JQ164+KB164+KM164+KX164+LI164+LT164 -> 0
A11: 6 | B11: ='Datos Iniciales'!T14 -> Alumno6 | C11: =SUMPRODUCT(D$4:M$4,D11:M11) -> 9.55 | D11: 9 | E11: 10 | F11: 10 | G11: 10 | H11: 9 | I11: 9 | J11: 10 | N11: =SUMPRODUCT(O$4:X$4,O11:X11) -> 9.6 | O11: 10 | P11: 9 | Q11: 10 | R11: 9 | S11: 10 | Y11: =SUMPRODUCT(Z$4:AI$4,Z11:AI11) -> 9.6 | Z11: 10 | AA11: 9 | AB11: 10 | AC11: 9 | AD11: 10 | AJ11: =SUMPRODUCT(AK$4:AT$4,AK11:AT11) -> 9.6 | AK11: 10 | AL11: 9 | AM11: 10 | AN11: 9 | AO11: 10 | AU11: =SUMPRODUCT(AV$4:BE$4,AV11:BE11) -> 9.7 | AV11: 9 | AW11: 10 | AX11: 10 | AY11: 10 | AZ11: 9 | BF11: =SUMPRODUCT(BG$4:BP$4,BG11:BP11) -> 9.6 | BG11: 9 | BH11: 10 | BI11: 10 | BJ11: 10 | BK11: 9 | BQ11: =SUMPRODUCT(BR$4:CA$4,BR11:CA11) -> 6.8 | BR11: 6 | BS11: 7 | BT11: 8 | BU11: 9 | BV11: 5 | CB11: =SUMPRODUCT(CC$4:CL$4,CC11:CL11) -> 0 | CM11: =SUMPRODUCT(CN$4:CW$4,CN11:CW11) -> 0 | CX11: =SUMPRODUCT(CY$4:DH$4,CY11:DH11) -> 0 | DI11: =SUMPRODUCT(DJ$4:DS$4,DJ11:DS11) -> 0 | DT11: =SUMPRODUCT(DU$4:ED$4,DU11:ED11) -> 0 | EE11: =SUMPRODUCT(EF$4:EO$4,EF11:EO11) -> 0 | EP11: =SUMPRODUCT(EQ$4:EZ$4,EQ11:EZ11) -> 0 | FA11: =SUMPRODUCT(FB$4:FK$4,FB11:FK11) -> 0 | FL11: =SUMPRODUCT(FM$4:FV$4,FM11:FV11) -> 0 | FW11: =SUMPRODUCT(FX$4:GG$4,FX11:GG11) -> 0 | GH11: =SUMPRODUCT(GI$4:GR$4,GI11:GR11) -> 0 | GS11: =SUMPRODUCT(GT$4:HC$4,GT11:HC11) -> 0 | HD11: =SUMPRODUCT(HE$4:HN$4,HE11:HN11) -> 0 | HO11: =SUMPRODUCT(HP$4:HY$4,HP11:HY11) -> 0 | HZ11: =SUMPRODUCT(IA$4:IJ$4,IA11:IJ11) -> 0 | IK11: =SUMPRODUCT(IL$4:IU$4,IL11:IU11) -> 0 | IV11: =SUMPRODUCT(IW$4:JF$4,IW11:JF11) -> 0 | JG11: =SUMPRODUCT(JH$4:JQ$4,JH11:JQ11) -> 0 | JR11: =SUMPRODUCT(JS$4:KB$4,JS11:KB11) -> 0 | KC11: =SUMPRODUCT(KD$4:KM$4,KD11:KM11) -> 0 | KN11: =SUMPRODUCT(KO$4:KX$4,KO11:KX11) -> 0 | KY11: =SUMPRODUCT(KZ$4:LI$4,KZ11:LI11) -> 0 | LJ11: =SUMPRODUCT(LK$4:LT$4,LK11:LT11) -> 0 | LX11: =D165+O165+Z165+AK165+AV165+BG165+BR165+CC165+CN165+CY165+DJ165+DU165+EF165+EQ165+FB165+FM165+FX165+GI165+GT165+HE165+HP165+IA165+IL165+IW165+JH165+JS165+KD165+KO165+KZ165+LK165 -> 9.4875 | LY11: =E165+P165+AA165+AL165+AW165+BH165+BS165+CD165+CO165+CZ165+DK165+DV165+EG165+ER165+FC165+FN165+FY165+GJ165+GU165+HF165+HQ165+IB165+IM165+IX165+JI165+JT165+KE165+KP165+LA165+LL165 -> 9.55 | LZ11: =F165+Q165+AB165+AM165+AX165+BI165+BT165+CE165+CP165+DA165+DL165+DW165+EH165+ES165+FD165+FO165+FZ165+GK165+GV165+HG165+HR165+IC165+IN165+IY165+JJ165+JU165+KF165+KQ165+LB165+LM165 -> 9.475 | MA11: =G165+R165+AC165+AN165+AY165+BJ165+BU165+CF165+CQ165+DB165+DM165+DX165+EI165+ET165+FE165+FP165+GA165+GL165+GW165+HH165+HS165+ID165+IO165+IZ165+JK165+JV165+KG165+KR165+LC165+LN165 -> 7.96 | MB11: =H165+S165+AD165+AO165+AZ165+BK165+BV165+CG165+CR165+DC165+DN165+DY165+EJ165+EU165+FF165+FQ165+GB165+GM165+GX165+HI165+HT165+IE165+IP165+JA165+JL165+JW165+KH165+KS165+LD165+LO165 -> 0 | MC11: =I165+T165+AE165+AP165+BA165+BL165+BW165+CH165+CS165+DD165+DO165+DZ165+EK165+EV165+FG165+FR165+GC165+GN165+GY165+HJ165+HU165+IF165+IQ165+JB165+JM165+JX165+KI165+KT165+LE165+LP165 -> 0 | MD11: =J165+U165+AF165+AQ165+BB165+BM165+BX165+CI165+CT165+DE165+DP165+EA165+EL165+EW165+FH165+FS165+GD165+GO165+GZ165+HK165+HV165+IG165+IR165+JC165+JN165+JY165+KJ165+KU165+LF165+LQ165 -> 0 | ME11: =K165+V165+AG165+AR165+BC165+BN165+BY165+CJ165+CU165+DF165+DQ165+EB165+EM165+EX165+FI165+FT165+GE165+GP165+HA165+HL165+HW165+IH165+IS165+JD165+JO165+JZ165+KK165+KV165+LG165+LR165 -> 0 | ... MG11: =M165+X165+AI165+AT165+BE165+BP165+CA165+CL165+CW165+DH165+DS165+ED165+EO165+EZ165+FK165+FV165+GG165+GR165+HC165+HN165+HY165+IJ165+IU165+JF165+JQ165+KB165+KM165+KX165+LI165+LT165 -> 0
A12: 7 | B12: ='Datos Iniciales'!T15 -> Alumno7 | C12: =SUMPRODUCT(D$4:M$4,D12:M12) -> 8.85 | D12: 9 | E12: 9 | F12: 9 | G12: 9 | H12: 9 | I12: 8 | J12: 9 | N12: =SUMPRODUCT(O$4:X$4,O12:X12) -> 9 | O12: 9 | P12: 9 | Q12: 9 | R12: 9 | S12: 9 | Y12: =SUMPRODUCT(Z$4:AI$4,Z12:AI12) -> 9 | Z12: 9 | AA12: 9 | AB12: 9 | AC12: 9 | AD12: 9 | AJ12: =SUMPRODUCT(AK$4:AT$4,AK12:AT12) -> 9 | AK12: 9 | AL12: 9 | AM12: 9 | AN12: 9 | AO12: 9 | AU12: =SUMPRODUCT(AV$4:BE$4,AV12:BE12) -> 9 | AV12: 9 | AW12: 9 | AX12: 9 | AY12: 9 | AZ12: 9 | BF12: =SUMPRODUCT(BG$4:BP$4,BG12:BP12) -> 9 | BG12: 9 | BH12: 9 | BI12: 9 | BJ12: 9 | BK12: 9 | BQ12: =SUMPRODUCT(BR$4:CA$4,BR12:CA12) -> 4.5 | BR12: 5 | BS12: 6 | BT12: 3 | BU12: 4 | BV12: 5 | CB12: =SUMPRODUCT(CC$4:CL$4,CC12:CL12) -> 0 | CM12: =SUMPRODUCT(CN$4:CW$4,CN12:CW12) -> 0 | CX12: =SUMPRODUCT(CY$4:DH$4,CY12:DH12) -> 0 | DI12: =SUMPRODUCT(DJ$4:DS$4,DJ12:DS12) -> 0 | DT12: =SUMPRODUCT(DU$4:ED$4,DU12:ED12) -> 0 | EE12: =SUMPRODUCT(EF$4:EO$4,EF12:EO12) -> 0 | EP12: =SUMPRODUCT(EQ$4:EZ$4,EQ12:EZ12) -> 0 | FA12: =SUMPRODUCT(FB$4:FK$4,FB12:FK12) -> 0 | FL12: =SUMPRODUCT(FM$4:FV$4,FM12:FV12) -> 0 | FW12: =SUMPRODUCT(FX$4:GG$4,FX12:GG12) -> 0 | GH12: =SUMPRODUCT(GI$4:GR$4,GI12:GR12) -> 0 | GS12: =SUMPRODUCT(GT$4:HC$4,GT12:HC12) -> 0 | HD12: =SUMPRODUCT(HE$4:HN$4,HE12:HN12) -> 0 | HO12: =SUMPRODUCT(HP$4:HY$4,HP12:HY12) -> 0 | HZ12: =SUMPRODUCT(IA$4:IJ$4,IA12:IJ12) -> 0 | IK12: =SUMPRODUCT(IL$4:IU$4,IL12:IU12) -> 0 | IV12: =SUMPRODUCT(IW$4:JF$4,IW12:JF12) -> 0 | JG12: =SUMPRODUCT(JH$4:JQ$4,JH12:JQ12) -> 0 | JR12: =SUMPRODUCT(JS$4:KB$4,JS12:KB12) -> 0 | KC12: =SUMPRODUCT(KD$4:KM$4,KD12:KM12) -> 0 | KN12: =SUMPRODUCT(KO$4:KX$4,KO12:KX12) -> 0 | KY12: =SUMPRODUCT(KZ$4:LI$4,KZ12:LI12) -> 0 | LJ12: =SUMPRODUCT(LK$4:LT$4,LK12:LT12) -> 0 | LX12: =D166+O166+Z166+AK166+AV166+BG166+BR166+CC166+CN166+CY166+DJ166+DU166+EF166+EQ166+FB166+FM166+FX166+GI166+GT166+HE166+HP166+IA166+IL166+IW166+JH166+JS166+KD166+KO166+KZ166+LK166 -> 8.9625 | LY12: =E166+P166+AA166+AL166+AW166+BH166+BS166+CD166+CO166+CZ166+DK166+DV166+EG166+ER166+FC166+FN166+FY166+GJ166+GU166+HF166+HQ166+IB166+IM166+IX166+JI166+JT166+KE166+KP166+LA166+LL166 -> 8.8 | LZ12: =F166+Q166+AB166+AM166+AX166+BI166+BT166+CE166+CP166+DA166+DL166+DW166+EH166+ES166+FD166+FO166+FZ166+GK166+GV166+HG166+HR166+IC166+IN166+IY166+JJ166+JU166+KF166+KQ166+LB166+LM166 -> 8.25 | MA12: =G166+R166+AC166+AN166+AY166+BJ166+BU166+CF166+CQ166+DB166+DM166+DX166+EI166+ET166+FE166+FP166+GA166+GL166+GW166+HH166+HS166+ID166+IO166+IZ166+JK166+JV166+KG166+KR166+LC166+LN166 -> 6.8 | MB12: =H166+S166+AD166+AO166+AZ166+BK166+BV166+CG166+CR166+DC166+DN166+DY166+EJ166+EU166+FF166+FQ166+GB166+GM166+GX166+HI166+HT166+IE166+IP166+JA166+JL166+JW166+KH166+KS166+LD166+LO166 -> 0 | MC12: =I166+T166+AE166+AP166+BA166+BL166+BW166+CH166+CS166+DD166+DO166+DZ166+EK166+EV166+FG166+FR166+GC166+GN166+GY166+HJ166+HU166+IF166+IQ166+JB166+JM166+JX166+KI166+KT166+LE166+LP166 -> 0 | MD12: =J166+U166+AF166+AQ166+BB166+BM166+BX166+CI166+CT166+DE166+DP166+EA166+EL166+EW166+FH166+FS166+GD166+GO166+GZ166+HK166+HV166+IG166+IR166+JC166+JN166+JY166+KJ166+KU166+LF166+LQ166 -> 0 | ME12: =K166+V166+AG166+AR166+BC166+BN166+BY166+CJ166+CU166+DF166+DQ166+EB166+EM166+EX166+FI166+FT166+GE166+GP166+HA166+HL166+HW166+IH166+IS166+JD166+JO166+JZ166+KK166+KV166+LG166+LR166 -> 0 | ... MG12: =M166+X166+AI166+AT166+BE166+BP166+CA166+CL166+CW166+DH166+DS166+ED166+EO166+EZ166+FK166+FV166+GG166+GR166+HC166+HN166+HY166+IJ166+IU166+JF166+JQ166+KB166+KM166+KX166+LI166+LT166 -> 0
A13: 8 | B13: ='Datos Iniciales'!T16 -> Alumno8 | C13: =SUMPRODUCT(D$4:M$4,D13:M13) -> 9.65 | D13: 10 | E13: 9 | F13: 10 | G13: 9 | H13: 10 | I13: 10 | J13: 9 | N13: =SUMPRODUCT(O$4:X$4,O13:X13) -> 5 | O13: 5 | P13: 5 | Q13: 5 | R13: 5 | S13: 5 | Y13: =SUMPRODUCT(Z$4:AI$4,Z13:AI13) -> 5 | Z13: 5 | AA13: 5 | AB13: 5 | AC13: 5 | AD13: 5 | AJ13: =SUMPRODUCT(AK$4:AT$4,AK13:AT13) -> 5 | AK13: 5 | AL13: 5 | AM13: 5 | AN13: 5 | AO13: 5 | AU13: =SUMPRODUCT(AV$4:BE$4,AV13:BE13) -> 9.5 | AV13: 10 | AW13: 9 | AX13: 10 | AY13: 9 | AZ13: 10 | BF13: =SUMPRODUCT(BG$4:BP$4,BG13:BP13) -> 9.6 | BG13: 10 | BH13: 9 | BI13: 10 | BJ13: 9 | BK13: 10 | BQ13: =SUMPRODUCT(BR$4:CA$4,BR13:CA13) -> 6.8 | BR13: 6 | BS13: 7 | BT13: 8 | BU13: 9 | BV13: 5 | CB13: =SUMPRODUCT(CC$4:CL$4,CC13:CL13) -> 0 | CM13: =SUMPRODUCT(CN$4:CW$4,CN13:CW13) -> 0 | CX13: =SUMPRODUCT(CY$4:DH$4,CY13:DH13) -> 0 | DI13: =SUMPRODUCT(DJ$4:DS$4,DJ13:DS13) -> 0 | DT13: =SUMPRODUCT(DU$4:ED$4,DU13:ED13) -> 0 | EE13: =SUMPRODUCT(EF$4:EO$4,EF13:EO13) -> 0 | EP13: =SUMPRODUCT(EQ$4:EZ$4,EQ13:EZ13) -> 0 | FA13: =SUMPRODUCT(FB$4:FK$4,FB13:FK13) -> 0 | FL13: =SUMPRODUCT(FM$4:FV$4,FM13:FV13) -> 0 | FW13: =SUMPRODUCT(FX$4:GG$4,FX13:GG13) -> 0 | GH13: =SUMPRODUCT(GI$4:GR$4,GI13:GR13) -> 0 | GS13: =SUMPRODUCT(GT$4:HC$4,GT13:HC13) -> 0 | HD13: =SUMPRODUCT(HE$4:HN$4,HE13:HN13) -> 0 | HO13: =SUMPRODUCT(HP$4:HY$4,HP13:HY13) -> 0 | HZ13: =SUMPRODUCT(IA$4:IJ$4,IA13:IJ13) -> 0 | IK13: =SUMPRODUCT(IL$4:IU$4,IL13:IU13) -> 0 | IV13: =SUMPRODUCT(IW$4:JF$4,IW13:JF13) -> 0 | JG13: =SUMPRODUCT(JH$4:JQ$4,JH13:JQ13) -> 0 | JR13: =SUMPRODUCT(JS$4:KB$4,JS13:KB13) -> 0 | KC13: =SUMPRODUCT(KD$4:KM$4,KD13:KM13) -> 0 | KN13: =SUMPRODUCT(KO$4:KX$4,KO13:KX13) -> 0 | KY13: =SUMPRODUCT(KZ$4:LI$4,KZ13:LI13) -> 0 | LJ13: =SUMPRODUCT(LK$4:LT$4,LK13:LT13) -> 0 | LX13: =D167+O167+Z167+AK167+AV167+BG167+BR167+CC167+CN167+CY167+DJ167+DU167+EF167+EQ167+FB167+FM167+FX167+GI167+GT167+HE167+HP167+IA167+IL167+IW167+JH167+JS167+KD167+KO167+KZ167+LK167 -> 6.9125 | LY13: =E167+P167+AA167+AL167+AW167+BH167+BS167+CD167+CO167+CZ167+DK167+DV167+EG167+ER167+FC167+FN167+FY167+GJ167+GU167+HF167+HQ167+IB167+IM167+IX167+JI167+JT167+KE167+KP167+LA167+LL167 -> 6.05 | LZ13: =F167+Q167+AB167+AM167+AX167+BI167+BT167+CE167+CP167+DA167+DL167+DW167+EH167+ES167+FD167+FO167+FZ167+GK167+GV167+HG167+HR167+IC167+IN167+IY167+JJ167+JU167+KF167+KQ167+LB167+LM167 -> 7.22 | MA13: =G167+R167+AC167+AN167+AY167+BJ167+BU167+CF167+CQ167+DB167+DM167+DX167+EI167+ET167+FE167+FP167+GA167+GL167+GW167+HH167+HS167+ID167+IO167+IZ167+JK167+JV167+KG167+KR167+LC167+LN167 -> 8.14 | MB13: =H167+S167+AD167+AO167+AZ167+BK167+BV167+CG167+CR167+DC167+DN167+DY167+EJ167+EU167+FF167+FQ167+GB167+GM167+GX167+HI167+HT167+IE167+IP167+JA167+JL167+JW167+KH167+KS167+LD167+LO167 -> 0 | MC13: =I167+T167+AE167+AP167+BA167+BL167+BW167+CH167+CS167+DD167+DO167+DZ167+EK167+EV167+FG167+FR167+GC167+GN167+GY167+HJ167+HU167+IF167+IQ167+JB167+JM167+JX167+KI167+KT167+LE167+LP167 -> 0 | MD13: =J167+U167+AF167+AQ167+BB167+BM167+BX167+CI167+CT167+DE167+DP167+EA167+EL167+EW167+FH167+FS167+GD167+GO167+GZ167+HK167+HV167+IG167+IR167+JC167+JN167+JY167+KJ167+KU167+LF167+LQ167 -> 0 | ME13: =K167+V167+AG167+AR167+BC167+BN167+BY167+CJ167+CU167+DF167+DQ167+EB167+EM167+EX167+FI167+FT167+GE167+GP167+HA167+HL167+HW167+IH167+IS167+JD167+JO167+JZ167+KK167+KV167+LG167+LR167 -> 0 | ... MG13: =M167+X167+AI167+AT167+BE167+BP167+CA167+CL167+CW167+DH167+DS167+ED167+EO167+EZ167+FK167+FV167+GG167+GR167+HC167+HN167+HY167+IJ167+IU167+JF167+JQ167+KB167+KM167+KX167+LI167+LT167 -> 0
A14: 9 | B14: ='Datos Iniciales'!T17 -> Alumno9 | C14: =SUMPRODUCT(D$4:M$4,D14:M14) -> 6.4 | D14: 6 | E14: 7 | F14: 8 | G14: 9 | H14: 5 | I14: 4 | J14: 6 | N14: =SUMPRODUCT(O$4:X$4,O14:X14) -> 4.6 | O14: 5 | P14: 6 | Q14: 3 | R14: 4 | S14: 5 | Y14: =SUMPRODUCT(Z$4:AI$4,Z14:AI14) -> 4.6 | Z14: 5 | AA14: 6 | AB14: 3 | AC14: 4 | AD14: 5 | AJ14: =SUMPRODUCT(AK$4:AT$4,AK14:AT14) -> 4.6 | AK14: 5 | AL14: 6 | AM14: 3 | AN14: 4 | AO14: 5 | AU14: =SUMPRODUCT(AV$4:BE$4,AV14:BE14) -> 7.3 | AV14: 6 | AW14: 7 | AX14: 8 | AY14: 9 | AZ14: 5 | BF14: =SUMPRODUCT(BG$4:BP$4,BG14:BP14) -> 6.9 | BG14: 6 | BH14: 7 | BI14: 8 | BJ14: 9 | BK14: 5 | BQ14: =SUMPRODUCT(BR$4:CA$4,BR14:CA14) -> 5 | BR14: 5 | BS14: 5 | BT14: 5 | BU14: 5 | BV14: 5 | CB14: =SUMPRODUCT(CC$4:CL$4,CC14:CL14) -> 0 | CM14: =SUMPRODUCT(CN$4:CW$4,CN14:CW14) -> 0 | CX14: =SUMPRODUCT(CY$4:DH$4,CY14:DH14) -> 0 | DI14: =SUMPRODUCT(DJ$4:DS$4,DJ14:DS14) -> 0 | DT14: =SUMPRODUCT(DU$4:ED$4,DU14:ED14) -> 0 | EE14: =SUMPRODUCT(EF$4:EO$4,EF14:EO14) -> 0 | EP14: =SUMPRODUCT(EQ$4:EZ$4,EQ14:EZ14) -> 0 | FA14: =SUMPRODUCT(FB$4:FK$4,FB14:FK14) -> 0 | FL14: =SUMPRODUCT(FM$4:FV$4,FM14:FV14) -> 0 | FW14: =SUMPRODUCT(FX$4:GG$4,FX14:GG14) -> 0 | GH14: =SUMPRODUCT(GI$4:GR$4,GI14:GR14) -> 0 | GS14: =SUMPRODUCT(GT$4:HC$4,GT14:HC14) -> 0 | HD14: =SUMPRODUCT(HE$4:HN$4,HE14:HN14) -> 0 | HO14: =SUMPRODUCT(HP$4:HY$4,HP14:HY14) -> 0 | HZ14: =SUMPRODUCT(IA$4:IJ$4,IA14:IJ14) -> 0 | IK14: =SUMPRODUCT(IL$4:IU$4,IL14:IU14) -> 0 | IV14: =SUMPRODUCT(IW$4:JF$4,IW14:JF14) -> 0 | JG14: =SUMPRODUCT(JH$4:JQ$4,JH14:JQ14) -> 0 | JR14: =SUMPRODUCT(JS$4:KB$4,JS14:KB14) -> 0 | KC14: =SUMPRODUCT(KD$4:KM$4,KD14:KM14) -> 0 | KN14: =SUMPRODUCT(KO$4:KX$4,KO14:KX14) -> 0 | KY14: =SUMPRODUCT(KZ$4:LI$4,KZ14:LI14) -> 0 | LJ14: =SUMPRODUCT(LK$4:LT$4,LK14:LT14) -> 0 | LX14: =D168+O168+Z168+AK168+AV168+BG168+BR168+CC168+CN168+CY168+DJ168+DU168+EF168+EQ168+FB168+FM168+FX168+GI168+GT168+HE168+HP168+IA168+IL168+IW168+JH168+JS168+KD168+KO168+KZ168+LK168 -> 5.65 | LY14: =E168+P168+AA168+AL168+AW168+BH168+BS168+CD168+CO168+CZ168+DK168+DV168+EG168+ER168+FC168+FN168+FY168+GJ168+GU168+HF168+HQ168+IB168+IM168+IX168+JI168+JT168+KE168+KP168+LA168+LL168 -> 4.95 | LZ14: =F168+Q168+AB168+AM168+AX168+BI168+BT168+CE168+CP168+DA168+DL168+DW168+EH168+ES168+FD168+FO168+FZ168+GK168+GV168+HG168+HR168+IC168+IN168+IY168+JJ168+JU168+KF168+KQ168+LB168+LM168 -> 5.855 | MA14: =G168+R168+AC168+AN168+AY168+BJ168+BU168+CF168+CQ168+DB168+DM168+DX168+EI168+ET168+FE168+FP168+GA168+GL168+GW168+HH168+HS168+ID168+IO168+IZ168+JK168+JV168+KG168+KR168+LC168+LN168 -> 5.64 | MB14: =H168+S168+AD168+AO168+AZ168+BK168+BV168+CG168+CR168+DC168+DN168+DY168+EJ168+EU168+FF168+FQ168+GB168+GM168+GX168+HI168+HT168+IE168+IP168+JA168+JL168+JW168+KH168+KS168+LD168+LO168 -> 0 | MC14: =I168+T168+AE168+AP168+BA168+BL168+BW168+CH168+CS168+DD168+DO168+DZ168+EK168+EV168+FG168+FR168+GC168+GN168+GY168+HJ168+HU168+IF168+IQ168+JB168+JM168+JX168+KI168+KT168+LE168+LP168 -> 0 | MD14: =J168+U168+AF168+AQ168+BB168+BM168+BX168+CI168+CT168+DE168+DP168+EA168+EL168+EW168+FH168+FS168+GD168+GO168+GZ168+HK168+HV168+IG168+IR168+JC168+JN168+JY168+KJ168+KU168+LF168+LQ168 -> 0 | ME14: =K168+V168+AG168+AR168+BC168+BN168+BY168+CJ168+CU168+DF168+DQ168+EB168+EM168+EX168+FI168+FT168+GE168+GP168+HA168+HL168+HW168+IH168+IS168+JD168+JO168+JZ168+KK168+KV168+LG168+LR168 -> 0 | ... MG14: =M168+X168+AI168+AT168+BE168+BP168+CA168+CL168+CW168+DH168+DS168+ED168+EO168+EZ168+FK168+FV168+GG168+GR168+HC168+HN168+HY168+IJ168+IU168+JF168+JQ168+KB168+KM168+KX168+LI168+LT168 -> 0
A15: 10 | B15: ='Datos Iniciales'!T18 -> Alumno10 | C15: =SUMPRODUCT(D$4:M$4,D15:M15) -> 5 | D15: 5 | E15: 6 | F15: 3 | G15: 4 | H15: 5 | I15: 6 | J15: 7 | N15: =SUMPRODUCT(O$4:X$4,O15:X15) -> 5 | O15: 5 | P15: 5 | Q15: 5 | R15: 5 | S15: 5 | Y15: =SUMPRODUCT(Z$4:AI$4,Z15:AI15) -> 5 | Z15: 5 | AA15: 5 | AB15: 5 | AC15: 5 | AD15: 5 | AJ15: =SUMPRODUCT(AK$4:AT$4,AK15:AT15) -> 5 | AK15: 5 | AL15: 5 | AM15: 5 | AN15: 5 | AO15: 5 | AU15: =SUMPRODUCT(AV$4:BE$4,AV15:BE15) -> 4.5 | AV15: 5 | AW15: 6 | AX15: 3 | AY15: 4 | AZ15: 5 | BF15: =SUMPRODUCT(BG$4:BP$4,BG15:BP15) -> 4.6 | BG15: 5 | BH15: 6 | BI15: 3 | BJ15: 4 | BK15: 5 | BQ15: =SUMPRODUCT(BR$4:CA$4,BR15:CA15) -> 4.5 | BR15: 5 | BS15: 6 | BT15: 3 | BU15: 4 | BV15: 5 | CB15: =SUMPRODUCT(CC$4:CL$4,CC15:CL15) -> 0 | CM15: =SUMPRODUCT(CN$4:CW$4,CN15:CW15) -> 0 | CX15: =SUMPRODUCT(CY$4:DH$4,CY15:DH15) -> 0 | DI15: =SUMPRODUCT(DJ$4:DS$4,DJ15:DS15) -> 0 | DT15: =SUMPRODUCT(DU$4:ED$4,DU15:ED15) -> 0 | EE15: =SUMPRODUCT(EF$4:EO$4,EF15:EO15) -> 0 | EP15: =SUMPRODUCT(EQ$4:EZ$4,EQ15:EZ15) -> 0 | FA15: =SUMPRODUCT(FB$4:FK$4,FB15:FK15) -> 0 | FL15: =SUMPRODUCT(FM$4:FV$4,FM15:FV15) -> 0 | FW15: =SUMPRODUCT(FX$4:GG$4,FX15:GG15) -> 0 | GH15: =SUMPRODUCT(GI$4:GR$4,GI15:GR15) -> 0 | GS15: =SUMPRODUCT(GT$4:HC$4,GT15:HC15) -> 0 | HD15: =SUMPRODUCT(HE$4:HN$4,HE15:HN15) -> 0 | HO15: =SUMPRODUCT(HP$4:HY$4,HP15:HY15) -> 0 | HZ15: =SUMPRODUCT(IA$4:IJ$4,IA15:IJ15) -> 0 | IK15: =SUMPRODUCT(IL$4:IU$4,IL15:IU15) -> 0 | IV15: =SUMPRODUCT(IW$4:JF$4,IW15:JF15) -> 0 | JG15: =SUMPRODUCT(JH$4:JQ$4,JH15:JQ15) -> 0 | JR15: =SUMPRODUCT(JS$4:KB$4,JS15:KB15) -> 0 | KC15: =SUMPRODUCT(KD$4:KM$4,KD15:KM15) -> 0 | KN15: =SUMPRODUCT(KO$4:KX$4,KO15:KX15) -> 0 | KY15: =SUMPRODUCT(KZ$4:LI$4,KZ15:LI15) -> 0 | LJ15: =SUMPRODUCT(LK$4:LT$4,LK15:LT15) -> 0 | LX15: =D169+O169+Z169+AK169+AV169+BG169+BR169+CC169+CN169+CY169+DJ169+DU169+EF169+EQ169+FB169+FM169+FX169+GI169+GT169+HE169+HP169+IA169+IL169+IW169+JH169+JS169+KD169+KO169+KZ169+LK169 -> 5 | LY15: =E169+P169+AA169+AL169+AW169+BH169+BS169+CD169+CO169+CZ169+DK169+DV169+EG169+ER169+FC169+FN169+FY169+GJ169+GU169+HF169+HQ169+IB169+IM169+IX169+JI169+JT169+KE169+KP169+LA169+LL169 -> 5.25 | LZ15: =F169+Q169+AB169+AM169+AX169+BI169+BT169+CE169+CP169+DA169+DL169+DW169+EH169+ES169+FD169+FO169+FZ169+GK169+GV169+HG169+HR169+IC169+IN169+IY169+JJ169+JU169+KF169+KQ169+LB169+LM169 -> 4.23 | MA15: =G169+R169+AC169+AN169+AY169+BJ169+BU169+CF169+CQ169+DB169+DM169+DX169+EI169+ET169+FE169+FP169+GA169+GL169+GW169+HH169+HS169+ID169+IO169+IZ169+JK169+JV169+KG169+KR169+LC169+LN169 -> 4.64 | MB15: =H169+S169+AD169+AO169+AZ169+BK169+BV169+CG169+CR169+DC169+DN169+DY169+EJ169+EU169+FF169+FQ169+GB169+GM169+GX169+HI169+HT169+IE169+IP169+JA169+JL169+JW169+KH169+KS169+LD169+LO169 -> 0 | MC15: =I169+T169+AE169+AP169+BA169+BL169+BW169+CH169+CS169+DD169+DO169+DZ169+EK169+EV169+FG169+FR169+GC169+GN169+GY169+HJ169+HU169+IF169+IQ169+JB169+JM169+JX169+KI169+KT169+LE169+LP169 -> 0 | MD15: =J169+U169+AF169+AQ169+BB169+BM169+BX169+CI169+CT169+DE169+DP169+EA169+EL169+EW169+FH169+FS169+GD169+GO169+GZ169+HK169+HV169+IG169+IR169+JC169+JN169+JY169+KJ169+KU169+LF169+LQ169 -> 0 | ME15: =K169+V169+AG169+AR169+BC169+BN169+BY169+CJ169+CU169+DF169+DQ169+EB169+EM169+EX169+FI169+FT169+GE169+GP169+HA169+HL169+HW169+IH169+IS169+JD169+JO169+JZ169+KK169+KV169+LG169+LR169 -> 0 | ... MG15: =M169+X169+AI169+AT169+BE169+BP169+CA169+CL169+CW169+DH169+DS169+ED169+EO169+EZ169+FK169+FV169+GG169+GR169+HC169+HN169+HY169+IJ169+IU169+JF169+JQ169+KB169+KM169+KX169+LI169+LT169 -> 0
A16: 11 | B16: ='Datos Iniciales'!T19 -> Alumno11 | C16: =SUMPRODUCT(D$4:M$4,D16:M16) -> 6.9 | D16: 8 | E16: 5 | F16: 7 | G16: 4 | H16: 9 | I16: 8 | J16: 6 | N16: =SUMPRODUCT(O$4:X$4,O16:X16) -> 6.6 | O16: 8 | P16: 5 | Q16: 7 | R16: 4 | S16: 9 | Y16: =SUMPRODUCT(Z$4:AI$4,Z16:AI16) -> 9 | Z16: 9 | AA16: 9 | AB16: 9 | AC16: 9 | AD16: 9 | AJ16: =SUMPRODUCT(AK$4:AT$4,AK16:AT16) -> 9 | AK16: 9 | AL16: 9 | AM16: 9 | AN16: 9 | AO16: 9 | AU16: =SUMPRODUCT(AV$4:BE$4,AV16:BE16) -> 6.2 | AV16: 8 | AW16: 5 | AX16: 7 | AY16: 4 | AZ16: 9 | BF16: =SUMPRODUCT(BG$4:BP$4,BG16:BP16) -> 6.7 | BG16: 8 | BH16: 5 | BI16: 7 | BJ16: 4 | BK16: 9 | BQ16: =SUMPRODUCT(BR$4:CA$4,BR16:CA16) -> 5 | BR16: 5 | BS16: 5 | BT16: 5 | BU16: 5 | BV16: 5 | CB16: =SUMPRODUCT(CC$4:CL$4,CC16:CL16) -> 0 | CM16: =SUMPRODUCT(CN$4:CW$4,CN16:CW16) -> 0 | CX16: =SUMPRODUCT(CY$4:DH$4,CY16:DH16) -> 0 | DI16: =SUMPRODUCT(DJ$4:DS$4,DJ16:DS16) -> 0 | DT16: =SUMPRODUCT(DU$4:ED$4,DU16:ED16) -> 0 | EE16: =SUMPRODUCT(EF$4:EO$4,EF16:EO16) -> 0 | EP16: =SUMPRODUCT(EQ$4:EZ$4,EQ16:EZ16) -> 0 | FA16: =SUMPRODUCT(FB$4:FK$4,FB16:FK16) -> 0 | FL16: =SUMPRODUCT(FM$4:FV$4,FM16:FV16) -> 0 | FW16: =SUMPRODUCT(FX$4:GG$4,FX16:GG16) -> 0 | GH16: =SUMPRODUCT(GI$4:GR$4,GI16:GR16) -> 0 | GS16: =SUMPRODUCT(GT$4:HC$4,GT16:HC16) -> 0 | HD16: =SUMPRODUCT(HE$4:HN$4,HE16:HN16) -> 0 | HO16: =SUMPRODUCT(HP$4:HY$4,HP16:HY16) -> 0 | HZ16: =SUMPRODUCT(IA$4:IJ$4,IA16:IJ16) -> 0 | IK16: =SUMPRODUCT(IL$4:IU$4,IL16:IU16) -> 0 | IV16: =SUMPRODUCT(IW$4:JF$4,IW16:JF16) -> 0 | JG16: =SUMPRODUCT(JH$4:JQ$4,JH16:JQ16) -> 0 | JR16: =SUMPRODUCT(JS$4:KB$4,JS16:KB16) -> 0 | KC16: =SUMPRODUCT(KD$4:KM$4,KD16:KM16) -> 0 | KN16: =SUMPRODUCT(KO$4:KX$4,KO16:KX16) -> 0 | KY16: =SUMPRODUCT(KZ$4:LI$4,KZ16:LI16) -> 0 | LJ16: =SUMPRODUCT(LK$4:LT$4,LK16:LT16) -> 0 | LX16: =D170+O170+Z170+AK170+AV170+BG170+BR170+CC170+CN170+CY170+DJ170+DU170+EF170+EQ170+FB170+FM170+FX170+GI170+GT170+HE170+HP170+IA170+IL170+IW170+JH170+JS170+KD170+KO170+KZ170+LK170 -> 7.825 | LY16: =E170+P170+AA170+AL170+AW170+BH170+BS170+CD170+CO170+CZ170+DK170+DV170+EG170+ER170+FC170+FN170+FY170+GJ170+GU170+HF170+HQ170+IB170+IM170+IX170+JI170+JT170+KE170+KP170+LA170+LL170 -> 7.4 | LZ16: =F170+Q170+AB170+AM170+AX170+BI170+BT170+CE170+CP170+DA170+DL170+DW170+EH170+ES170+FD170+FO170+FZ170+GK170+GV170+HG170+HR170+IC170+IN170+IY170+JJ170+JU170+KF170+KQ170+LB170+LM170 -> 7.06 | MA16: =G170+R170+AC170+AN170+AY170+BJ170+BU170+CF170+CQ170+DB170+DM170+DX170+EI170+ET170+FE170+FP170+GA170+GL170+GW170+HH170+HS170+ID170+IO170+IZ170+JK170+JV170+KG170+KR170+LC170+LN170 -> 6.2 | MB16: =H170+S170+AD170+AO170+AZ170+BK170+BV170+CG170+CR170+DC170+DN170+DY170+EJ170+EU170+FF170+FQ170+GB170+GM170+GX170+HI170+HT170+IE170+IP170+JA170+JL170+JW170+KH170+KS170+LD170+LO170 -> 0 | MC16: =I170+T170+AE170+AP170+BA170+BL170+BW170+CH170+CS170+DD170+DO170+DZ170+EK170+EV170+FG170+FR170+GC170+GN170+GY170+HJ170+HU170+IF170+IQ170+JB170+JM170+JX170+KI170+KT170+LE170+LP170 -> 0 | MD16: =J170+U170+AF170+AQ170+BB170+BM170+BX170+CI170+CT170+DE170+DP170+EA170+EL170+EW170+FH170+FS170+GD170+GO170+GZ170+HK170+HV170+IG170+IR170+JC170+JN170+JY170+KJ170+KU170+LF170+LQ170 -> 0 | ME16: =K170+V170+AG170+AR170+BC170+BN170+BY170+CJ170+CU170+DF170+DQ170+EB170+EM170+EX170+FI170+FT170+GE170+GP170+HA170+HL170+HW170+IH170+IS170+JD170+JO170+JZ170+KK170+KV170+LG170+LR170 -> 0 | ... MG16: =M170+X170+AI170+AT170+BE170+BP170+CA170+CL170+CW170+DH170+DS170+ED170+EO170+EZ170+FK170+FV170+GG170+GR170+HC170+HN170+HY170+IJ170+IU170+JF170+JQ170+KB170+KM170+KX170+LI170+LT170 -> 0
A17: 12 | B17: ='Datos Iniciales'!T20 -> Alumno12 | C17: =SUMPRODUCT(D$4:M$4,D17:M17) -> 5 | D17: 5 | E17: 5 | F17: 5 | G17: 5 | H17: 5 | I17: 5 | J17: 5 | N17: =SUMPRODUCT(O$4:X$4,O17:X17) -> 5 | O17: 5 | P17: 5 | Q17: 5 | R17: 5 | S17: 5 | Y17: =SUMPRODUCT(Z$4:AI$4,Z17:AI17) -> 5 | Z17: 5 | AA17: 5 | AB17: 5 | AC17: 5 | AD17: 5 | AJ17: =SUMPRODUCT(AK$4:AT$4,AK17:AT17) -> 5 | AK17: 5 | AL17: 5 | AM17: 5 | AN17: 5 | AO17: 5 | AU17: =SUMPRODUCT(AV$4:BE$4,AV17:BE17) -> 5 | AV17: 5 | AW17: 5 | AX17: 5 | AY17: 5 | AZ17: 5 | BF17: =SUMPRODUCT(BG$4:BP$4,BG17:BP17) -> 5 | BG17: 5 | BH17: 5 | BI17: 5 | BJ17: 5 | BK17: 5 | BQ17: =SUMPRODUCT(BR$4:CA$4,BR17:CA17) -> 9 | BR17: 9 | BS17: 9 | BT17: 9 | BU17: 9 | BV17: 9 | CB17: =SUMPRODUCT(CC$4:CL$4,CC17:CL17) -> 0 | CM17: =SUMPRODUCT(CN$4:CW$4,CN17:CW17) -> 0 | CX17: =SUMPRODUCT(CY$4:DH$4,CY17:DH17) -> 0 | DI17: =SUMPRODUCT(DJ$4:DS$4,DJ17:DS17) -> 0 | DT17: =SUMPRODUCT(DU$4:ED$4,DU17:ED17) -> 0 | EE17: =SUMPRODUCT(EF$4:EO$4,EF17:EO17) -> 0 | EP17: =SUMPRODUCT(EQ$4:EZ$4,EQ17:EZ17) -> 0 | FA17: =SUMPRODUCT(FB$4:FK$4,FB17:FK17) -> 0 | FL17: =SUMPRODUCT(FM$4:FV$4,FM17:FV17) -> 0 | FW17: =SUMPRODUCT(FX$4:GG$4,FX17:GG17) -> 0 | GH17: =SUMPRODUCT(GI$4:GR$4,GI17:GR17) -> 0 | GS17: =SUMPRODUCT(GT$4:HC$4,GT17:HC17) -> 0 | HD17: =SUMPRODUCT(HE$4:HN$4,HE17:HN17) -> 0 | HO17: =SUMPRODUCT(HP$4:HY$4,HP17:HY17) -> 0 | HZ17: =SUMPRODUCT(IA$4:IJ$4,IA17:IJ17) -> 0 | IK17: =SUMPRODUCT(IL$4:IU$4,IL17:IU17) -> 0 | IV17: =SUMPRODUCT(IW$4:JF$4,IW17:JF17) -> 0 | JG17: =SUMPRODUCT(JH$4:JQ$4,JH17:JQ17) -> 0 | JR17: =SUMPRODUCT(JS$4:KB$4,JS17:KB17) -> 0 | KC17: =SUMPRODUCT(KD$4:KM$4,KD17:KM17) -> 0 | KN17: =SUMPRODUCT(KO$4:KX$4,KO17:KX17) -> 0 | KY17: =SUMPRODUCT(KZ$4:LI$4,KZ17:LI17) -> 0 | LJ17: =SUMPRODUCT(LK$4:LT$4,LK17:LT17) -> 0 | LX17: =D171+O171+Z171+AK171+AV171+BG171+BR171+CC171+CN171+CY171+DJ171+DU171+EF171+EQ171+FB171+FM171+FX171+GI171+GT171+HE171+HP171+IA171+IL171+IW171+JH171+JS171+KD171+KO171+KZ171+LK171 -> 5 | LY17: =E171+P171+AA171+AL171+AW171+BH171+BS171+CD171+CO171+CZ171+DK171+DV171+EG171+ER171+FC171+FN171+FY171+GJ171+GU171+HF171+HQ171+IB171+IM171+IX171+JI171+JT171+KE171+KP171+LA171+LL171 -> 5.2 | LZ17: =F171+Q171+AB171+AM171+AX171+BI171+BT171+CE171+CP171+DA171+DL171+DW171+EH171+ES171+FD171+FO171+FZ171+GK171+GV171+HG171+HR171+IC171+IN171+IY171+JJ171+JU171+KF171+KQ171+LB171+LM171 -> 5.6 | MA17: =G171+R171+AC171+AN171+AY171+BJ171+BU171+CF171+CQ171+DB171+DM171+DX171+EI171+ET171+FE171+FP171+GA171+GL171+GW171+HH171+HS171+ID171+IO171+IZ171+JK171+JV171+KG171+KR171+LC171+LN171 -> 7 | MB17: =H171+S171+AD171+AO171+AZ171+BK171+BV171+CG171+CR171+DC171+DN171+DY171+EJ171+EU171+FF171+FQ171+GB171+GM171+GX171+HI171+HT171+IE171+IP171+JA171+JL171+JW171+KH171+KS171+LD171+LO171 -> 0 | MC17: =I171+T171+AE171+AP171+BA171+BL171+BW171+CH171+CS171+DD171+DO171+DZ171+EK171+EV171+FG171+FR171+GC171+GN171+GY171+HJ171+HU171+IF171+IQ171+JB171+JM171+JX171+KI171+KT171+LE171+LP171 -> 0 | MD17: =J171+U171+AF171+AQ171+BB171+BM171+BX171+CI171+CT171+DE171+DP171+EA171+EL171+EW171+FH171+FS171+GD171+GO171+GZ171+HK171+HV171+IG171+IR171+JC171+JN171+JY171+KJ171+KU171+LF171+LQ171 -> 0 | ME17: =K171+V171+AG171+AR171+BC171+BN171+BY171+CJ171+CU171+DF171+DQ171+EB171+EM171+EX171+FI171+FT171+GE171+GP171+HA171+HL171+HW171+IH171+IS171+JD171+JO171+JZ171+KK171+KV171+LG171+LR171 -> 0 | ... MG17: =M171+X171+AI171+AT171+BE171+BP171+CA171+CL171+CW171+DH171+DS171+ED171+EO171+EZ171+FK171+FV171+GG171+GR171+HC171+HN171+HY171+IJ171+IU171+JF171+JQ171+KB171+KM171+KX171+LI171+LT171 -> 0
